{
    "registryname": "large_particle_accelerator",
    "localizedname": "Large Particle Accelerator",
    "modifiers": [
        {
            "elements": "modularmachinery:blockinputbus",
            "x": 0,
            "y": 0,
            "z": 1,
            "description": "Replace fluid input with item input\nto rip apart matter instead of\ncreating exotic matter",
            "modifier": {
                "target": "modularmachinery:item",
                "io": "input",
                "operation": 1,
                "multiplier": 1.0
            }
        }
    ],
    "parts": [
        {
            "x": -1,
            "y": -1,
            "z": 32,
            "elements": [
                "nuclearcraft:accelerator_electromagnet_active@0"
            ]
        },
        {
            "x": -48,
            "y": -1,
            "z": 15,
            "elements": [
                "nuclearcraft:electromagnet_supercooler_active@0"
            ]
        },
        {
            "x": -32,
            "y": 1,
            "z": 0,
            "elements": [
                "nuclearcraft:electromagnet_supercooler_active@0"
            ]
        },
        {
            "x": -31,
            "y": 1,
            "z": 0,
            "elements": [
                "nuclearcraft:electromagnet_supercooler_active@0"
            ]
        },
        {
            "x": -16,
            "y": 1,
            "z": 49,
            "elements": [
                "nuclearcraft:accelerator_electromagnet_active@0"
            ]
        },
        {
            "x": -1,
            "y": 0,
            "z": 0,
            "elements": [
                "modularmachinery:blockoutputbus"
            ]
        },
        {
            "x": 0,
            "y": -1,
            "z": 32,
            "elements": [
                "nuclearcraft:electromagnet_supercooler_active@0"
            ]
        },
        {
            "x": -2,
            "y": 0,
            "z": 0,
            "elements": [
                "nuclearcraft:accelerator_electromagnet_active@0"
            ]
        },
        {
            "x": -33,
            "y": 1,
            "z": 0,
            "elements": [
                "nuclearcraft:electromagnet_supercooler_active@0"
            ]
        },
        {
            "x": -30,
            "y": 1,
            "z": 0,
            "elements": [
                "nuclearcraft:electromagnet_supercooler_active@0"
            ]
        },
        {
            "x": -15,
            "y": 1,
            "z": 49,
            "elements": [
                "nuclearcraft:accelerator_electromagnet_active@0"
            ]
        },
        {
            "x": -3,
            "y": 0,
            "z": 0,
            "elements": [
                "nuclearcraft:accelerator_electromagnet_active@0"
            ]
        },
        {
            "x": -34,
            "y": 1,
            "z": 0,
            "elements": [
                "nuclearcraft:electromagnet_supercooler_active@0"
            ]
        },
        {
            "x": -29,
            "y": 1,
            "z": 0,
            "elements": [
                "nuclearcraft:electromagnet_supercooler_active@0"
            ]
        },
        {
            "x": -14,
            "y": 1,
            "z": 49,
            "elements": [
                "nuclearcraft:accelerator_electromagnet_active@0"
            ]
        },
        {
            "x": -4,
            "y": 0,
            "z": 0,
            "elements": [
                "nuclearcraft:accelerator_electromagnet_active@0"
            ]
        },
        {
            "x": -35,
            "y": 1,
            "z": 0,
            "elements": [
                "nuclearcraft:electromagnet_supercooler_active@0"
            ]
        },
        {
            "x": -28,
            "y": 1,
            "z": 0,
            "elements": [
                "nuclearcraft:electromagnet_supercooler_active@0"
            ]
        },
        {
            "x": -13,
            "y": 1,
            "z": 49,
            "elements": [
                "nuclearcraft:accelerator_electromagnet_active@0"
            ]
        },
        {
            "x": -5,
            "y": 0,
            "z": 0,
            "elements": [
                "nuclearcraft:accelerator_electromagnet_active@0"
            ]
        },
        {
            "x": -36,
            "y": 1,
            "z": 0,
            "elements": [
                "nuclearcraft:electromagnet_supercooler_active@0"
            ]
        },
        {
            "x": -27,
            "y": 1,
            "z": 0,
            "elements": [
                "nuclearcraft:electromagnet_supercooler_active@0"
            ]
        },
        {
            "x": -12,
            "y": 1,
            "z": 49,
            "elements": [
                "nuclearcraft:accelerator_electromagnet_active@0"
            ]
        },
        {
            "x": -6,
            "y": 0,
            "z": 0,
            "elements": [
                "nuclearcraft:accelerator_electromagnet_active@0"
            ]
        },
        {
            "x": -37,
            "y": 1,
            "z": 0,
            "elements": [
                "nuclearcraft:electromagnet_supercooler_active@0"
            ]
        },
        {
            "x": -26,
            "y": 1,
            "z": 0,
            "elements": [
                "nuclearcraft:electromagnet_supercooler_active@0"
            ]
        },
        {
            "x": -11,
            "y": 1,
            "z": 49,
            "elements": [
                "nuclearcraft:accelerator_electromagnet_active@0"
            ]
        },
        {
            "x": -7,
            "y": 0,
            "z": 0,
            "elements": [
                "nuclearcraft:accelerator_electromagnet_active@0"
            ]
        },
        {
            "x": -38,
            "y": 1,
            "z": 0,
            "elements": [
                "nuclearcraft:electromagnet_supercooler_active@0"
            ]
        },
        {
            "x": -25,
            "y": 1,
            "z": 0,
            "elements": [
                "nuclearcraft:electromagnet_supercooler_active@0"
            ]
        },
        {
            "x": -10,
            "y": 1,
            "z": 49,
            "elements": [
                "nuclearcraft:accelerator_electromagnet_active@0"
            ]
        },
        {
            "x": -8,
            "y": 0,
            "z": 0,
            "elements": [
                "nuclearcraft:accelerator_electromagnet_active@0"
            ]
        },
        {
            "x": -39,
            "y": 1,
            "z": 0,
            "elements": [
                "nuclearcraft:electromagnet_supercooler_active@0"
            ]
        },
        {
            "x": -24,
            "y": 1,
            "z": 0,
            "elements": [
                "nuclearcraft:electromagnet_supercooler_active@0"
            ]
        },
        {
            "x": -9,
            "y": 1,
            "z": 49,
            "elements": [
                "nuclearcraft:accelerator_electromagnet_active@0"
            ]
        },
        {
            "x": -9,
            "y": 0,
            "z": 0,
            "elements": [
                "nuclearcraft:accelerator_electromagnet_active@0"
            ]
        },
        {
            "x": -40,
            "y": 1,
            "z": 0,
            "elements": [
                "nuclearcraft:electromagnet_supercooler_active@0"
            ]
        },
        {
            "x": -23,
            "y": 1,
            "z": 0,
            "elements": [
                "nuclearcraft:electromagnet_supercooler_active@0"
            ]
        },
        {
            "x": -8,
            "y": 1,
            "z": 49,
            "elements": [
                "nuclearcraft:accelerator_electromagnet_active@0"
            ]
        },
        {
            "x": -10,
            "y": 0,
            "z": 0,
            "elements": [
                "nuclearcraft:accelerator_electromagnet_active@0"
            ]
        },
        {
            "x": -41,
            "y": 1,
            "z": 0,
            "elements": [
                "nuclearcraft:electromagnet_supercooler_active@0"
            ]
        },
        {
            "x": -22,
            "y": 1,
            "z": 0,
            "elements": [
                "nuclearcraft:electromagnet_supercooler_active@0"
            ]
        },
        {
            "x": -7,
            "y": 1,
            "z": 49,
            "elements": [
                "nuclearcraft:accelerator_electromagnet_active@0"
            ]
        },
        {
            "x": -11,
            "y": 0,
            "z": 0,
            "elements": [
                "nuclearcraft:accelerator_electromagnet_active@0"
            ]
        },
        {
            "x": -42,
            "y": 1,
            "z": 0,
            "elements": [
                "nuclearcraft:electromagnet_supercooler_active@0"
            ]
        },
        {
            "x": -21,
            "y": 1,
            "z": 0,
            "elements": [
                "nuclearcraft:electromagnet_supercooler_active@0"
            ]
        },
        {
            "x": -6,
            "y": 1,
            "z": 49,
            "elements": [
                "nuclearcraft:accelerator_electromagnet_active@0"
            ]
        },
        {
            "x": -12,
            "y": 0,
            "z": 0,
            "elements": [
                "nuclearcraft:accelerator_electromagnet_active@0"
            ]
        },
        {
            "x": -43,
            "y": 1,
            "z": 0,
            "elements": [
                "nuclearcraft:electromagnet_supercooler_active@0"
            ]
        },
        {
            "x": -20,
            "y": 1,
            "z": 0,
            "elements": [
                "nuclearcraft:electromagnet_supercooler_active@0"
            ]
        },
        {
            "x": -5,
            "y": 1,
            "z": 49,
            "elements": [
                "nuclearcraft:accelerator_electromagnet_active@0"
            ]
        },
        {
            "x": -13,
            "y": 0,
            "z": 0,
            "elements": [
                "nuclearcraft:accelerator_electromagnet_active@0"
            ]
        },
        {
            "x": -44,
            "y": 1,
            "z": 0,
            "elements": [
                "nuclearcraft:electromagnet_supercooler_active@0"
            ]
        },
        {
            "x": -19,
            "y": 1,
            "z": 0,
            "elements": [
                "nuclearcraft:electromagnet_supercooler_active@0"
            ]
        },
        {
            "x": -4,
            "y": 1,
            "z": 49,
            "elements": [
                "nuclearcraft:accelerator_electromagnet_active@0"
            ]
        },
        {
            "x": -14,
            "y": 0,
            "z": 0,
            "elements": [
                "nuclearcraft:accelerator_electromagnet_active@0"
            ]
        },
        {
            "x": -45,
            "y": 1,
            "z": 0,
            "elements": [
                "nuclearcraft:electromagnet_supercooler_active@0"
            ]
        },
        {
            "x": -18,
            "y": 1,
            "z": 0,
            "elements": [
                "nuclearcraft:electromagnet_supercooler_active@0"
            ]
        },
        {
            "x": -3,
            "y": 1,
            "z": 49,
            "elements": [
                "nuclearcraft:accelerator_electromagnet_active@0"
            ]
        },
        {
            "x": -50,
            "y": 1,
            "z": 32,
            "elements": [
                "nuclearcraft:electromagnet_supercooler_active@0"
            ]
        },
        {
            "x": -15,
            "y": 0,
            "z": 0,
            "elements": [
                "nuclearcraft:accelerator_electromagnet_active@0"
            ]
        },
        {
            "x": -46,
            "y": 1,
            "z": 0,
            "elements": [
                "nuclearcraft:electromagnet_supercooler_active@0"
            ]
        },
        {
            "x": -17,
            "y": 1,
            "z": 0,
            "elements": [
                "nuclearcraft:electromagnet_supercooler_active@0"
            ]
        },
        {
            "x": -2,
            "y": 1,
            "z": 49,
            "elements": [
                "nuclearcraft:accelerator_electromagnet_active@0"
            ]
        },
        {
            "x": -49,
            "y": 1,
            "z": 32,
            "elements": [
                "nuclearcraft:accelerator_electromagnet_active@0"
            ]
        },
        {
            "x": -16,
            "y": 0,
            "z": 0,
            "elements": [
                "nuclearcraft:accelerator_electromagnet_active@0"
            ]
        },
        {
            "x": -47,
            "y": 1,
            "z": 0,
            "elements": [
                "nuclearcraft:electromagnet_supercooler_active@0"
            ]
        },
        {
            "x": -16,
            "y": 1,
            "z": 0,
            "elements": [
                "nuclearcraft:electromagnet_supercooler_active@0"
            ]
        },
        {
            "x": -1,
            "y": 1,
            "z": 49,
            "elements": [
                "nuclearcraft:accelerator_electromagnet_active@0"
            ]
        },
        {
            "x": -48,
            "y": 1,
            "z": 32,
            "elements": [
                "nuclearcraft:electromagnet_supercooler_active@0"
            ]
        },
        {
            "x": -17,
            "y": 0,
            "z": 0,
            "elements": [
                "nuclearcraft:accelerator_electromagnet_active@0"
            ]
        },
        {
            "x": -48,
            "y": 1,
            "z": 0,
            "elements": [
                "nuclearcraft:electromagnet_supercooler_active@0"
            ]
        },
        {
            "x": -15,
            "y": 1,
            "z": 0,
            "elements": [
                "nuclearcraft:electromagnet_supercooler_active@0"
            ]
        },
        {
            "x": 0,
            "y": 1,
            "z": 49,
            "elements": [
                "nuclearcraft:electromagnet_supercooler_active@0"
            ]
        },
        {
            "x": -18,
            "y": 0,
            "z": 0,
            "elements": [
                "nuclearcraft:accelerator_electromagnet_active@0"
            ]
        },
        {
            "x": -49,
            "y": 1,
            "z": 0,
            "elements": [
                "nuclearcraft:electromagnet_supercooler_active@0"
            ]
        },
        {
            "x": -14,
            "y": 1,
            "z": 0,
            "elements": [
                "nuclearcraft:electromagnet_supercooler_active@0"
            ]
        },
        {
            "x": -19,
            "y": 0,
            "z": 0,
            "elements": [
                "nuclearcraft:accelerator_electromagnet_active@0"
            ]
        },
        {
            "x": -50,
            "y": 1,
            "z": 0,
            "elements": [
                "nuclearcraft:electromagnet_supercooler_active@0"
            ]
        },
        {
            "x": -13,
            "y": 1,
            "z": 0,
            "elements": [
                "nuclearcraft:electromagnet_supercooler_active@0"
            ]
        },
        {
            "x": -20,
            "y": 0,
            "z": 0,
            "elements": [
                "nuclearcraft:accelerator_electromagnet_active@0"
            ]
        },
        {
            "x": -12,
            "y": 1,
            "z": 0,
            "elements": [
                "nuclearcraft:electromagnet_supercooler_active@0"
            ]
        },
        {
            "x": -21,
            "y": 0,
            "z": 0,
            "elements": [
                "nuclearcraft:accelerator_electromagnet_active@0"
            ]
        },
        {
            "x": -11,
            "y": 1,
            "z": 0,
            "elements": [
                "nuclearcraft:electromagnet_supercooler_active@0"
            ]
        },
        {
            "x": -22,
            "y": 0,
            "z": 0,
            "elements": [
                "nuclearcraft:accelerator_electromagnet_active@0"
            ]
        },
        {
            "x": -10,
            "y": 1,
            "z": 0,
            "elements": [
                "nuclearcraft:electromagnet_supercooler_active@0"
            ]
        },
        {
            "x": -23,
            "y": 0,
            "z": 0,
            "elements": [
                "nuclearcraft:accelerator_electromagnet_active@0"
            ]
        },
        {
            "x": -9,
            "y": 1,
            "z": 0,
            "elements": [
                "nuclearcraft:electromagnet_supercooler_active@0"
            ]
        },
        {
            "x": -24,
            "y": 0,
            "z": 0,
            "elements": [
                "nuclearcraft:accelerator_electromagnet_active@0"
            ]
        },
        {
            "x": -8,
            "y": 1,
            "z": 0,
            "elements": [
                "nuclearcraft:electromagnet_supercooler_active@0"
            ]
        },
        {
            "x": -25,
            "y": 0,
            "z": 0,
            "elements": [
                "nuclearcraft:accelerator_electromagnet_active@0"
            ]
        },
        {
            "x": -7,
            "y": 1,
            "z": 0,
            "elements": [
                "nuclearcraft:electromagnet_supercooler_active@0"
            ]
        },
        {
            "x": -26,
            "y": 0,
            "z": 0,
            "elements": [
                "nuclearcraft:accelerator_electromagnet_active@0"
            ]
        },
        {
            "x": -6,
            "y": 1,
            "z": 0,
            "elements": [
                "nuclearcraft:electromagnet_supercooler_active@0"
            ]
        },
        {
            "x": -27,
            "y": 0,
            "z": 0,
            "elements": [
                "nuclearcraft:accelerator_electromagnet_active@0"
            ]
        },
        {
            "x": -5,
            "y": 1,
            "z": 0,
            "elements": [
                "nuclearcraft:electromagnet_supercooler_active@0"
            ]
        },
        {
            "x": -28,
            "y": 0,
            "z": 0,
            "elements": [
                "nuclearcraft:accelerator_electromagnet_active@0"
            ]
        },
        {
            "x": -4,
            "y": 1,
            "z": 0,
            "elements": [
                "nuclearcraft:electromagnet_supercooler_active@0"
            ]
        },
        {
            "x": -29,
            "y": 0,
            "z": 0,
            "elements": [
                "nuclearcraft:accelerator_electromagnet_active@0"
            ]
        },
        {
            "x": -3,
            "y": 1,
            "z": 0,
            "elements": [
                "nuclearcraft:electromagnet_supercooler_active@0"
            ]
        },
        {
            "x": -50,
            "y": 0,
            "z": 15,
            "elements": [
                "nuclearcraft:accelerator_electromagnet_active@0"
            ]
        },
        {
            "x": -30,
            "y": 0,
            "z": 0,
            "elements": [
                "nuclearcraft:accelerator_electromagnet_active@0"
            ]
        },
        {
            "x": -2,
            "y": 1,
            "z": 0,
            "elements": [
                "nuclearcraft:electromagnet_supercooler_active@0"
            ]
        },
        {
            "x": 0,
            "y": -1,
            "z": 0,
            "elements": [
                "nuclearcraft:electromagnet_supercooler_active@0"
            ]
        },
        {
            "x": -50,
            "y": -1,
            "z": 47,
            "elements": [
                "nuclearcraft:electromagnet_supercooler_active@0"
            ]
        },
        {
            "x": -31,
            "y": 0,
            "z": 0,
            "elements": [
                "nuclearcraft:accelerator_electromagnet_active@0"
            ]
        },
        {
            "x": -2,
            "y": 0,
            "z": 32,
            "elements": [
                "nuclearcraft:accelerator_electromagnet_active@0"
            ]
        },
        {
            "x": -1,
            "y": 1,
            "z": 0,
            "elements": [
                "nuclearcraft:electromagnet_supercooler_active@0"
            ]
        },
        {
            "x": -1,
            "y": -1,
            "z": 0,
            "elements": [
                "nuclearcraft:electromagnet_supercooler_active@0"
            ]
        },
        {
            "x": -49,
            "y": -1,
            "z": 47,
            "elements": [
                "nuclearcraft:accelerator_electromagnet_active@0"
            ]
        },
        {
            "x": -32,
            "y": 0,
            "z": 0,
            "elements": [
                "nuclearcraft:accelerator_electromagnet_active@0"
            ]
        },
        {
            "x": -48,
            "y": 0,
            "z": 15,
            "elements": [
                "nuclearcraft:accelerator_electromagnet_active@0"
            ]
        },
        {
            "x": 0,
            "y": 1,
            "z": 0,
            "elements": [
                "nuclearcraft:electromagnet_supercooler_active@0"
            ]
        },
        {
            "x": -2,
            "y": -1,
            "z": 0,
            "elements": [
                "nuclearcraft:electromagnet_supercooler_active@0"
            ]
        },
        {
            "x": -48,
            "y": -1,
            "z": 47,
            "elements": [
                "nuclearcraft:electromagnet_supercooler_active@0"
            ]
        },
        {
            "x": -33,
            "y": 0,
            "z": 0,
            "elements": [
                "nuclearcraft:accelerator_electromagnet_active@0"
            ]
        },
        {
            "x": 0,
            "y": 0,
            "z": 32,
            "elements": [
                "nuclearcraft:accelerator_electromagnet_active@0"
            ]
        },
        {
            "x": -3,
            "y": -1,
            "z": 0,
            "elements": [
                "nuclearcraft:electromagnet_supercooler_active@0"
            ]
        },
        {
            "x": -34,
            "y": 0,
            "z": 0,
            "elements": [
                "nuclearcraft:accelerator_electromagnet_active@0"
            ]
        },
        {
            "x": -4,
            "y": -1,
            "z": 0,
            "elements": [
                "nuclearcraft:electromagnet_supercooler_active@0"
            ]
        },
        {
            "x": -35,
            "y": 0,
            "z": 0,
            "elements": [
                "nuclearcraft:accelerator_electromagnet_active@0"
            ]
        },
        {
            "x": -5,
            "y": -1,
            "z": 0,
            "elements": [
                "nuclearcraft:electromagnet_supercooler_active@0"
            ]
        },
        {
            "x": -36,
            "y": 0,
            "z": 0,
            "elements": [
                "nuclearcraft:accelerator_electromagnet_active@0"
            ]
        },
        {
            "x": -6,
            "y": -1,
            "z": 0,
            "elements": [
                "nuclearcraft:electromagnet_supercooler_active@0"
            ]
        },
        {
            "x": -37,
            "y": 0,
            "z": 0,
            "elements": [
                "nuclearcraft:accelerator_electromagnet_active@0"
            ]
        },
        {
            "x": -7,
            "y": -1,
            "z": 0,
            "elements": [
                "nuclearcraft:electromagnet_supercooler_active@0"
            ]
        },
        {
            "x": -38,
            "y": 0,
            "z": 0,
            "elements": [
                "nuclearcraft:accelerator_electromagnet_active@0"
            ]
        },
        {
            "x": -8,
            "y": -1,
            "z": 0,
            "elements": [
                "nuclearcraft:electromagnet_supercooler_active@0"
            ]
        },
        {
            "x": -39,
            "y": 0,
            "z": 0,
            "elements": [
                "nuclearcraft:accelerator_electromagnet_active@0"
            ]
        },
        {
            "x": -9,
            "y": -1,
            "z": 0,
            "elements": [
                "nuclearcraft:electromagnet_supercooler_active@0"
            ]
        },
        {
            "x": -40,
            "y": 0,
            "z": 0,
            "elements": [
                "nuclearcraft:accelerator_electromagnet_active@0"
            ]
        },
        {
            "x": -10,
            "y": -1,
            "z": 0,
            "elements": [
                "nuclearcraft:electromagnet_supercooler_active@0"
            ]
        },
        {
            "x": -41,
            "y": 0,
            "z": 0,
            "elements": [
                "nuclearcraft:accelerator_electromagnet_active@0"
            ]
        },
        {
            "x": -11,
            "y": -1,
            "z": 0,
            "elements": [
                "nuclearcraft:electromagnet_supercooler_active@0"
            ]
        },
        {
            "x": -42,
            "y": 0,
            "z": 0,
            "elements": [
                "nuclearcraft:accelerator_electromagnet_active@0"
            ]
        },
        {
            "x": -12,
            "y": -1,
            "z": 0,
            "elements": [
                "nuclearcraft:electromagnet_supercooler_active@0"
            ]
        },
        {
            "x": -43,
            "y": 0,
            "z": 0,
            "elements": [
                "nuclearcraft:accelerator_electromagnet_active@0"
            ]
        },
        {
            "x": -13,
            "y": -1,
            "z": 0,
            "elements": [
                "nuclearcraft:electromagnet_supercooler_active@0"
            ]
        },
        {
            "x": -44,
            "y": 0,
            "z": 0,
            "elements": [
                "nuclearcraft:accelerator_electromagnet_active@0"
            ]
        },
        {
            "x": -14,
            "y": -1,
            "z": 0,
            "elements": [
                "nuclearcraft:electromagnet_supercooler_active@0"
            ]
        },
        {
            "x": -45,
            "y": 0,
            "z": 0,
            "elements": [
                "nuclearcraft:accelerator_electromagnet_active@0"
            ]
        },
        {
            "x": -15,
            "y": -1,
            "z": 0,
            "elements": [
                "nuclearcraft:electromagnet_supercooler_active@0"
            ]
        },
        {
            "x": -46,
            "y": 0,
            "z": 0,
            "elements": [
                "nuclearcraft:accelerator_electromagnet_active@0"
            ]
        },
        {
            "x": -2,
            "y": -1,
            "z": 15,
            "elements": [
                "nuclearcraft:electromagnet_supercooler_active@0"
            ]
        },
        {
            "x": -16,
            "y": -1,
            "z": 0,
            "elements": [
                "nuclearcraft:electromagnet_supercooler_active@0"
            ]
        },
        {
            "x": -47,
            "y": 0,
            "z": 0,
            "elements": [
                "nuclearcraft:accelerator_electromagnet_active@0"
            ]
        },
        {
            "x": -1,
            "y": -1,
            "z": 15,
            "elements": [
                "nuclearcraft:accelerator_electromagnet_active@0"
            ]
        },
        {
            "x": -17,
            "y": -1,
            "z": 0,
            "elements": [
                "nuclearcraft:electromagnet_supercooler_active@0"
            ]
        },
        {
            "x": -48,
            "y": 0,
            "z": 0,
            "elements": [
                "nuclearcraft:accelerator_electromagnet_active@0"
            ]
        },
        {
            "x": 0,
            "y": -1,
            "z": 15,
            "elements": [
                "nuclearcraft:electromagnet_supercooler_active@0"
            ]
        },
        {
            "x": -18,
            "y": -1,
            "z": 0,
            "elements": [
                "nuclearcraft:electromagnet_supercooler_active@0"
            ]
        },
        {
            "x": -49,
            "y": 0,
            "z": 0,
            "elements": [
                "nuclearcraft:accelerator_electromagnet_active@0"
            ]
        },
        {
            "x": -19,
            "y": -1,
            "z": 0,
            "elements": [
                "nuclearcraft:electromagnet_supercooler_active@0"
            ]
        },
        {
            "x": -50,
            "y": 0,
            "z": 0,
            "elements": [
                "nuclearcraft:accelerator_electromagnet_active@0"
            ]
        },
        {
            "x": -20,
            "y": -1,
            "z": 0,
            "elements": [
                "nuclearcraft:electromagnet_supercooler_active@0"
            ]
        },
        {
            "x": -21,
            "y": -1,
            "z": 0,
            "elements": [
                "nuclearcraft:electromagnet_supercooler_active@0"
            ]
        },
        {
            "x": -22,
            "y": -1,
            "z": 0,
            "elements": [
                "nuclearcraft:electromagnet_supercooler_active@0"
            ]
        },
        {
            "x": -23,
            "y": -1,
            "z": 0,
            "elements": [
                "nuclearcraft:electromagnet_supercooler_active@0"
            ]
        },
        {
            "x": -24,
            "y": -1,
            "z": 0,
            "elements": [
                "nuclearcraft:electromagnet_supercooler_active@0"
            ]
        },
        {
            "x": -25,
            "y": -1,
            "z": 0,
            "elements": [
                "nuclearcraft:electromagnet_supercooler_active@0"
            ]
        },
        {
            "x": -26,
            "y": -1,
            "z": 0,
            "elements": [
                "nuclearcraft:electromagnet_supercooler_active@0"
            ]
        },
        {
            "x": -27,
            "y": -1,
            "z": 0,
            "elements": [
                "nuclearcraft:electromagnet_supercooler_active@0"
            ]
        },
        {
            "x": -28,
            "y": -1,
            "z": 0,
            "elements": [
                "nuclearcraft:electromagnet_supercooler_active@0"
            ]
        },
        {
            "x": -29,
            "y": -1,
            "z": 0,
            "elements": [
                "nuclearcraft:electromagnet_supercooler_active@0"
            ]
        },
        {
            "x": -30,
            "y": -1,
            "z": 0,
            "elements": [
                "nuclearcraft:electromagnet_supercooler_active@0"
            ]
        },
        {
            "x": -50,
            "y": 1,
            "z": 15,
            "elements": [
                "nuclearcraft:electromagnet_supercooler_active@0"
            ]
        },
        {
            "x": -31,
            "y": -1,
            "z": 0,
            "elements": [
                "nuclearcraft:electromagnet_supercooler_active@0"
            ]
        },
        {
            "x": -50,
            "y": 0,
            "z": 47,
            "elements": [
                "nuclearcraft:accelerator_electromagnet_active@0"
            ]
        },
        {
            "x": -2,
            "y": 1,
            "z": 32,
            "elements": [
                "nuclearcraft:electromagnet_supercooler_active@0"
            ]
        },
        {
            "x": -49,
            "y": 1,
            "z": 15,
            "elements": [
                "nuclearcraft:accelerator_electromagnet_active@0"
            ]
        },
        {
            "x": -32,
            "y": -1,
            "z": 0,
            "elements": [
                "nuclearcraft:electromagnet_supercooler_active@0"
            ]
        },
        {
            "x": -1,
            "y": 1,
            "z": 32,
            "elements": [
                "nuclearcraft:accelerator_electromagnet_active@0"
            ]
        },
        {
            "x": -48,
            "y": 1,
            "z": 15,
            "elements": [
                "nuclearcraft:electromagnet_supercooler_active@0"
            ]
        },
        {
            "x": -33,
            "y": -1,
            "z": 0,
            "elements": [
                "nuclearcraft:electromagnet_supercooler_active@0"
            ]
        },
        {
            "x": -48,
            "y": 0,
            "z": 47,
            "elements": [
                "nuclearcraft:accelerator_electromagnet_active@0"
            ]
        },
        {
            "x": 0,
            "y": 1,
            "z": 32,
            "elements": [
                "nuclearcraft:electromagnet_supercooler_active@0"
            ]
        },
        {
            "x": -34,
            "y": -1,
            "z": 0,
            "elements": [
                "nuclearcraft:electromagnet_supercooler_active@0"
            ]
        },
        {
            "x": -35,
            "y": -1,
            "z": 0,
            "elements": [
                "nuclearcraft:electromagnet_supercooler_active@0"
            ]
        },
        {
            "x": -36,
            "y": -1,
            "z": 0,
            "elements": [
                "nuclearcraft:electromagnet_supercooler_active@0"
            ]
        },
        {
            "x": -37,
            "y": -1,
            "z": 0,
            "elements": [
                "nuclearcraft:electromagnet_supercooler_active@0"
            ]
        },
        {
            "x": -38,
            "y": -1,
            "z": 0,
            "elements": [
                "nuclearcraft:electromagnet_supercooler_active@0"
            ]
        },
        {
            "x": -39,
            "y": -1,
            "z": 0,
            "elements": [
                "nuclearcraft:electromagnet_supercooler_active@0"
            ]
        },
        {
            "x": -40,
            "y": -1,
            "z": 0,
            "elements": [
                "nuclearcraft:electromagnet_supercooler_active@0"
            ]
        },
        {
            "x": -41,
            "y": -1,
            "z": 0,
            "elements": [
                "nuclearcraft:electromagnet_supercooler_active@0"
            ]
        },
        {
            "x": -42,
            "y": -1,
            "z": 0,
            "elements": [
                "nuclearcraft:electromagnet_supercooler_active@0"
            ]
        },
        {
            "x": -43,
            "y": -1,
            "z": 0,
            "elements": [
                "nuclearcraft:electromagnet_supercooler_active@0"
            ]
        },
        {
            "x": -44,
            "y": -1,
            "z": 0,
            "elements": [
                "nuclearcraft:electromagnet_supercooler_active@0"
            ]
        },
        {
            "x": -45,
            "y": -1,
            "z": 0,
            "elements": [
                "nuclearcraft:electromagnet_supercooler_active@0"
            ]
        },
        {
            "x": -46,
            "y": -1,
            "z": 0,
            "elements": [
                "nuclearcraft:electromagnet_supercooler_active@0"
            ]
        },
        {
            "x": -47,
            "y": -1,
            "z": 0,
            "elements": [
                "nuclearcraft:electromagnet_supercooler_active@0"
            ]
        },
        {
            "x": -50,
            "y": -1,
            "z": 30,
            "elements": [
                "nuclearcraft:electromagnet_supercooler_active@0"
            ]
        },
        {
            "x": -2,
            "y": 0,
            "z": 15,
            "elements": [
                "nuclearcraft:accelerator_electromagnet_active@0"
            ]
        },
        {
            "x": -2,
            "y": -1,
            "z": 47,
            "elements": [
                "nuclearcraft:electromagnet_supercooler_active@0"
            ]
        },
        {
            "x": -48,
            "y": -1,
            "z": 0,
            "elements": [
                "nuclearcraft:electromagnet_supercooler_active@0"
            ]
        },
        {
            "x": -49,
            "y": -1,
            "z": 30,
            "elements": [
                "nuclearcraft:accelerator_electromagnet_active@0"
            ]
        },
        {
            "x": -1,
            "y": -1,
            "z": 47,
            "elements": [
                "nuclearcraft:accelerator_electromagnet_active@0"
            ]
        },
        {
            "x": -49,
            "y": -1,
            "z": 0,
            "elements": [
                "nuclearcraft:electromagnet_supercooler_active@0"
            ]
        },
        {
            "x": -48,
            "y": -1,
            "z": 30,
            "elements": [
                "nuclearcraft:electromagnet_supercooler_active@0"
            ]
        },
        {
            "x": 0,
            "y": 0,
            "z": 15,
            "elements": [
                "nuclearcraft:accelerator_electromagnet_active@0"
            ]
        },
        {
            "x": 0,
            "y": -1,
            "z": 47,
            "elements": [
                "nuclearcraft:electromagnet_supercooler_active@0"
            ]
        },
        {
            "x": -50,
            "y": -1,
            "z": 0,
            "elements": [
                "nuclearcraft:electromagnet_supercooler_active@0"
            ]
        },
        {
            "x": -50,
            "y": 1,
            "z": 47,
            "elements": [
                "nuclearcraft:electromagnet_supercooler_active@0"
            ]
        },
        {
            "x": -49,
            "y": 1,
            "z": 47,
            "elements": [
                "nuclearcraft:accelerator_electromagnet_active@0"
            ]
        },
        {
            "x": -48,
            "y": 1,
            "z": 47,
            "elements": [
                "nuclearcraft:electromagnet_supercooler_active@0"
            ]
        },
        {
            "x": -50,
            "y": 0,
            "z": 30,
            "elements": [
                "nuclearcraft:accelerator_electromagnet_active@0"
            ]
        },
        {
            "x": -2,
            "y": 1,
            "z": 15,
            "elements": [
                "nuclearcraft:electromagnet_supercooler_active@0"
            ]
        },
        {
            "x": -2,
            "y": 0,
            "z": 47,
            "elements": [
                "nuclearcraft:accelerator_electromagnet_active@0"
            ]
        },
        {
            "x": -1,
            "y": 1,
            "z": 15,
            "elements": [
                "nuclearcraft:accelerator_electromagnet_active@0"
            ]
        },
        {
            "x": -48,
            "y": 0,
            "z": 30,
            "elements": [
                "nuclearcraft:accelerator_electromagnet_active@0"
            ]
        },
        {
            "x": 0,
            "y": 1,
            "z": 15,
            "elements": [
                "nuclearcraft:electromagnet_supercooler_active@0"
            ]
        },
        {
            "x": 0,
            "y": 0,
            "z": 47,
            "elements": [
                "nuclearcraft:accelerator_electromagnet_active@0"
            ]
        },
        {
            "x": -50,
            "y": -1,
            "z": 13,
            "elements": [
                "nuclearcraft:electromagnet_supercooler_active@0"
            ]
        },
        {
            "x": -2,
            "y": -1,
            "z": 30,
            "elements": [
                "nuclearcraft:electromagnet_supercooler_active@0"
            ]
        },
        {
            "x": -49,
            "y": -1,
            "z": 13,
            "elements": [
                "nuclearcraft:accelerator_electromagnet_active@0"
            ]
        },
        {
            "x": -1,
            "y": -1,
            "z": 30,
            "elements": [
                "nuclearcraft:accelerator_electromagnet_active@0"
            ]
        },
        {
            "x": -48,
            "y": -1,
            "z": 13,
            "elements": [
                "nuclearcraft:electromagnet_supercooler_active@0"
            ]
        },
        {
            "x": 0,
            "y": -1,
            "z": 30,
            "elements": [
                "nuclearcraft:electromagnet_supercooler_active@0"
            ]
        },
        {
            "x": -50,
            "y": 1,
            "z": 30,
            "elements": [
                "nuclearcraft:electromagnet_supercooler_active@0"
            ]
        },
        {
            "x": -2,
            "y": 1,
            "z": 47,
            "elements": [
                "nuclearcraft:electromagnet_supercooler_active@0"
            ]
        },
        {
            "x": -49,
            "y": 1,
            "z": 30,
            "elements": [
                "nuclearcraft:accelerator_electromagnet_active@0"
            ]
        },
        {
            "x": -1,
            "y": 1,
            "z": 47,
            "elements": [
                "nuclearcraft:accelerator_electromagnet_active@0"
            ]
        },
        {
            "x": -48,
            "y": 1,
            "z": 30,
            "elements": [
                "nuclearcraft:electromagnet_supercooler_active@0"
            ]
        },
        {
            "x": 0,
            "y": 1,
            "z": 47,
            "elements": [
                "nuclearcraft:electromagnet_supercooler_active@0"
            ]
        },
        {
            "x": -50,
            "y": 0,
            "z": 13,
            "elements": [
                "nuclearcraft:accelerator_electromagnet_active@0"
            ]
        },
        {
            "x": -50,
            "y": -1,
            "z": 45,
            "elements": [
                "nuclearcraft:electromagnet_supercooler_active@0"
            ]
        },
        {
            "x": -2,
            "y": 0,
            "z": 30,
            "elements": [
                "nuclearcraft:accelerator_electromagnet_active@0"
            ]
        },
        {
            "x": -49,
            "y": -1,
            "z": 45,
            "elements": [
                "nuclearcraft:accelerator_electromagnet_active@0"
            ]
        },
        {
            "x": -48,
            "y": 0,
            "z": 13,
            "elements": [
                "nuclearcraft:accelerator_electromagnet_active@0"
            ]
        },
        {
            "x": -48,
            "y": -1,
            "z": 45,
            "elements": [
                "nuclearcraft:electromagnet_supercooler_active@0"
            ]
        },
        {
            "x": 0,
            "y": 0,
            "z": 30,
            "elements": [
                "nuclearcraft:accelerator_electromagnet_active@0"
            ]
        },
        {
            "x": -2,
            "y": -1,
            "z": 13,
            "elements": [
                "nuclearcraft:electromagnet_supercooler_active@0"
            ]
        },
        {
            "x": -1,
            "y": -1,
            "z": 13,
            "elements": [
                "nuclearcraft:accelerator_electromagnet_active@0"
            ]
        },
        {
            "x": 0,
            "y": -1,
            "z": 13,
            "elements": [
                "nuclearcraft:electromagnet_supercooler_active@0"
            ]
        },
        {
            "x": -50,
            "y": 1,
            "z": 13,
            "elements": [
                "nuclearcraft:electromagnet_supercooler_active@0"
            ]
        },
        {
            "x": -50,
            "y": 0,
            "z": 45,
            "elements": [
                "nuclearcraft:accelerator_electromagnet_active@0"
            ]
        },
        {
            "x": -2,
            "y": 1,
            "z": 30,
            "elements": [
                "nuclearcraft:electromagnet_supercooler_active@0"
            ]
        },
        {
            "x": -49,
            "y": 1,
            "z": 13,
            "elements": [
                "nuclearcraft:accelerator_electromagnet_active@0"
            ]
        },
        {
            "x": -1,
            "y": 1,
            "z": 30,
            "elements": [
                "nuclearcraft:accelerator_electromagnet_active@0"
            ]
        },
        {
            "x": -48,
            "y": 1,
            "z": 13,
            "elements": [
                "nuclearcraft:electromagnet_supercooler_active@0"
            ]
        },
        {
            "x": -48,
            "y": 0,
            "z": 45,
            "elements": [
                "nuclearcraft:accelerator_electromagnet_active@0"
            ]
        },
        {
            "x": 0,
            "y": 1,
            "z": 30,
            "elements": [
                "nuclearcraft:electromagnet_supercooler_active@0"
            ]
        },
        {
            "x": -50,
            "y": -1,
            "z": 28,
            "elements": [
                "nuclearcraft:electromagnet_supercooler_active@0"
            ]
        },
        {
            "x": -2,
            "y": 0,
            "z": 13,
            "elements": [
                "nuclearcraft:accelerator_electromagnet_active@0"
            ]
        },
        {
            "x": -2,
            "y": -1,
            "z": 45,
            "elements": [
                "nuclearcraft:electromagnet_supercooler_active@0"
            ]
        },
        {
            "x": -49,
            "y": -1,
            "z": 28,
            "elements": [
                "nuclearcraft:accelerator_electromagnet_active@0"
            ]
        },
        {
            "x": -1,
            "y": -1,
            "z": 45,
            "elements": [
                "nuclearcraft:accelerator_electromagnet_active@0"
            ]
        },
        {
            "x": -48,
            "y": -1,
            "z": 28,
            "elements": [
                "nuclearcraft:electromagnet_supercooler_active@0"
            ]
        },
        {
            "x": 0,
            "y": 0,
            "z": 13,
            "elements": [
                "nuclearcraft:accelerator_electromagnet_active@0"
            ]
        },
        {
            "x": 0,
            "y": -1,
            "z": 45,
            "elements": [
                "nuclearcraft:electromagnet_supercooler_active@0"
            ]
        },
        {
            "x": -50,
            "y": 1,
            "z": 45,
            "elements": [
                "nuclearcraft:electromagnet_supercooler_active@0"
            ]
        },
        {
            "x": -49,
            "y": 1,
            "z": 45,
            "elements": [
                "nuclearcraft:accelerator_electromagnet_active@0"
            ]
        },
        {
            "x": -48,
            "y": 1,
            "z": 45,
            "elements": [
                "nuclearcraft:electromagnet_supercooler_active@0"
            ]
        },
        {
            "x": -50,
            "y": 0,
            "z": 28,
            "elements": [
                "nuclearcraft:accelerator_electromagnet_active@0"
            ]
        },
        {
            "x": -2,
            "y": 1,
            "z": 13,
            "elements": [
                "nuclearcraft:electromagnet_supercooler_active@0"
            ]
        },
        {
            "x": -2,
            "y": 0,
            "z": 45,
            "elements": [
                "nuclearcraft:accelerator_electromagnet_active@0"
            ]
        },
        {
            "x": -1,
            "y": 1,
            "z": 13,
            "elements": [
                "nuclearcraft:accelerator_electromagnet_active@0"
            ]
        },
        {
            "x": -48,
            "y": 0,
            "z": 28,
            "elements": [
                "nuclearcraft:accelerator_electromagnet_active@0"
            ]
        },
        {
            "x": 0,
            "y": 1,
            "z": 13,
            "elements": [
                "nuclearcraft:electromagnet_supercooler_active@0"
            ]
        },
        {
            "x": 0,
            "y": 0,
            "z": 45,
            "elements": [
                "nuclearcraft:accelerator_electromagnet_active@0"
            ]
        },
        {
            "x": -50,
            "y": -1,
            "z": 11,
            "elements": [
                "nuclearcraft:electromagnet_supercooler_active@0"
            ]
        },
        {
            "x": -2,
            "y": -1,
            "z": 28,
            "elements": [
                "nuclearcraft:electromagnet_supercooler_active@0"
            ]
        },
        {
            "x": -49,
            "y": -1,
            "z": 11,
            "elements": [
                "nuclearcraft:accelerator_electromagnet_active@0"
            ]
        },
        {
            "x": -1,
            "y": -1,
            "z": 28,
            "elements": [
                "nuclearcraft:accelerator_electromagnet_active@0"
            ]
        },
        {
            "x": -48,
            "y": -1,
            "z": 11,
            "elements": [
                "nuclearcraft:electromagnet_supercooler_active@0"
            ]
        },
        {
            "x": 0,
            "y": -1,
            "z": 28,
            "elements": [
                "nuclearcraft:electromagnet_supercooler_active@0"
            ]
        },
        {
            "x": -50,
            "y": 1,
            "z": 28,
            "elements": [
                "nuclearcraft:electromagnet_supercooler_active@0"
            ]
        },
        {
            "x": -2,
            "y": 1,
            "z": 45,
            "elements": [
                "nuclearcraft:electromagnet_supercooler_active@0"
            ]
        },
        {
            "x": -49,
            "y": 1,
            "z": 28,
            "elements": [
                "nuclearcraft:accelerator_electromagnet_active@0"
            ]
        },
        {
            "x": -1,
            "y": 1,
            "z": 45,
            "elements": [
                "nuclearcraft:accelerator_electromagnet_active@0"
            ]
        },
        {
            "x": -48,
            "y": 1,
            "z": 28,
            "elements": [
                "nuclearcraft:electromagnet_supercooler_active@0"
            ]
        },
        {
            "x": 0,
            "y": 1,
            "z": 45,
            "elements": [
                "nuclearcraft:electromagnet_supercooler_active@0"
            ]
        },
        {
            "x": -50,
            "y": 0,
            "z": 11,
            "elements": [
                "nuclearcraft:accelerator_electromagnet_active@0"
            ]
        },
        {
            "x": -50,
            "y": -1,
            "z": 43,
            "elements": [
                "nuclearcraft:electromagnet_supercooler_active@0"
            ]
        },
        {
            "x": -2,
            "y": 0,
            "z": 28,
            "elements": [
                "nuclearcraft:accelerator_electromagnet_active@0"
            ]
        },
        {
            "x": -49,
            "y": -1,
            "z": 43,
            "elements": [
                "nuclearcraft:accelerator_electromagnet_active@0"
            ]
        },
        {
            "x": -48,
            "y": 0,
            "z": 11,
            "elements": [
                "nuclearcraft:accelerator_electromagnet_active@0"
            ]
        },
        {
            "x": -48,
            "y": -1,
            "z": 43,
            "elements": [
                "nuclearcraft:electromagnet_supercooler_active@0"
            ]
        },
        {
            "x": 0,
            "y": 0,
            "z": 28,
            "elements": [
                "nuclearcraft:accelerator_electromagnet_active@0"
            ]
        },
        {
            "x": -2,
            "y": -1,
            "z": 11,
            "elements": [
                "nuclearcraft:electromagnet_supercooler_active@0"
            ]
        },
        {
            "x": -1,
            "y": -1,
            "z": 11,
            "elements": [
                "nuclearcraft:accelerator_electromagnet_active@0"
            ]
        },
        {
            "x": 0,
            "y": -1,
            "z": 11,
            "elements": [
                "nuclearcraft:electromagnet_supercooler_active@0"
            ]
        },
        {
            "x": -50,
            "y": 1,
            "z": 11,
            "elements": [
                "nuclearcraft:electromagnet_supercooler_active@0"
            ]
        },
        {
            "x": -50,
            "y": 0,
            "z": 43,
            "elements": [
                "nuclearcraft:accelerator_electromagnet_active@0"
            ]
        },
        {
            "x": -2,
            "y": 1,
            "z": 28,
            "elements": [
                "nuclearcraft:electromagnet_supercooler_active@0"
            ]
        },
        {
            "x": -49,
            "y": 1,
            "z": 11,
            "elements": [
                "nuclearcraft:accelerator_electromagnet_active@0"
            ]
        },
        {
            "x": -1,
            "y": 1,
            "z": 28,
            "elements": [
                "nuclearcraft:accelerator_electromagnet_active@0"
            ]
        },
        {
            "x": -48,
            "y": 1,
            "z": 11,
            "elements": [
                "nuclearcraft:electromagnet_supercooler_active@0"
            ]
        },
        {
            "x": -48,
            "y": 0,
            "z": 43,
            "elements": [
                "nuclearcraft:accelerator_electromagnet_active@0"
            ]
        },
        {
            "x": 0,
            "y": 1,
            "z": 28,
            "elements": [
                "nuclearcraft:electromagnet_supercooler_active@0"
            ]
        },
        {
            "x": -50,
            "y": -1,
            "z": 26,
            "elements": [
                "nuclearcraft:electromagnet_supercooler_active@0"
            ]
        },
        {
            "x": -2,
            "y": 0,
            "z": 11,
            "elements": [
                "nuclearcraft:accelerator_electromagnet_active@0"
            ]
        },
        {
            "x": -2,
            "y": -1,
            "z": 43,
            "elements": [
                "nuclearcraft:electromagnet_supercooler_active@0"
            ]
        },
        {
            "x": -49,
            "y": -1,
            "z": 26,
            "elements": [
                "nuclearcraft:accelerator_electromagnet_active@0"
            ]
        },
        {
            "x": -1,
            "y": -1,
            "z": 43,
            "elements": [
                "nuclearcraft:accelerator_electromagnet_active@0"
            ]
        },
        {
            "x": -48,
            "y": -1,
            "z": 26,
            "elements": [
                "nuclearcraft:electromagnet_supercooler_active@0"
            ]
        },
        {
            "x": 0,
            "y": 0,
            "z": 11,
            "elements": [
                "nuclearcraft:accelerator_electromagnet_active@0"
            ]
        },
        {
            "x": 0,
            "y": -1,
            "z": 43,
            "elements": [
                "nuclearcraft:electromagnet_supercooler_active@0"
            ]
        },
        {
            "x": -50,
            "y": 1,
            "z": 43,
            "elements": [
                "nuclearcraft:electromagnet_supercooler_active@0"
            ]
        },
        {
            "x": -49,
            "y": 1,
            "z": 43,
            "elements": [
                "nuclearcraft:accelerator_electromagnet_active@0"
            ]
        },
        {
            "x": -48,
            "y": 1,
            "z": 43,
            "elements": [
                "nuclearcraft:electromagnet_supercooler_active@0"
            ]
        },
        {
            "x": -50,
            "y": 0,
            "z": 26,
            "elements": [
                "nuclearcraft:accelerator_electromagnet_active@0"
            ]
        },
        {
            "x": -2,
            "y": 1,
            "z": 11,
            "elements": [
                "nuclearcraft:electromagnet_supercooler_active@0"
            ]
        },
        {
            "x": -2,
            "y": 0,
            "z": 43,
            "elements": [
                "nuclearcraft:accelerator_electromagnet_active@0"
            ]
        },
        {
            "x": -1,
            "y": 1,
            "z": 11,
            "elements": [
                "nuclearcraft:accelerator_electromagnet_active@0"
            ]
        },
        {
            "x": -48,
            "y": 0,
            "z": 26,
            "elements": [
                "nuclearcraft:accelerator_electromagnet_active@0"
            ]
        },
        {
            "x": 0,
            "y": 1,
            "z": 11,
            "elements": [
                "nuclearcraft:electromagnet_supercooler_active@0"
            ]
        },
        {
            "x": 0,
            "y": 0,
            "z": 43,
            "elements": [
                "nuclearcraft:accelerator_electromagnet_active@0"
            ]
        },
        {
            "x": -50,
            "y": -1,
            "z": 9,
            "elements": [
                "nuclearcraft:electromagnet_supercooler_active@0"
            ]
        },
        {
            "x": -2,
            "y": -1,
            "z": 26,
            "elements": [
                "nuclearcraft:electromagnet_supercooler_active@0"
            ]
        },
        {
            "x": -49,
            "y": -1,
            "z": 9,
            "elements": [
                "nuclearcraft:accelerator_electromagnet_active@0"
            ]
        },
        {
            "x": -1,
            "y": -1,
            "z": 26,
            "elements": [
                "nuclearcraft:accelerator_electromagnet_active@0"
            ]
        },
        {
            "x": -48,
            "y": -1,
            "z": 9,
            "elements": [
                "nuclearcraft:electromagnet_supercooler_active@0"
            ]
        },
        {
            "x": 0,
            "y": -1,
            "z": 26,
            "elements": [
                "nuclearcraft:electromagnet_supercooler_active@0"
            ]
        },
        {
            "x": -50,
            "y": 1,
            "z": 26,
            "elements": [
                "nuclearcraft:electromagnet_supercooler_active@0"
            ]
        },
        {
            "x": -2,
            "y": 1,
            "z": 43,
            "elements": [
                "nuclearcraft:electromagnet_supercooler_active@0"
            ]
        },
        {
            "x": -49,
            "y": 1,
            "z": 26,
            "elements": [
                "nuclearcraft:accelerator_electromagnet_active@0"
            ]
        },
        {
            "x": -1,
            "y": 1,
            "z": 43,
            "elements": [
                "nuclearcraft:accelerator_electromagnet_active@0"
            ]
        },
        {
            "x": -48,
            "y": 1,
            "z": 26,
            "elements": [
                "nuclearcraft:electromagnet_supercooler_active@0"
            ]
        },
        {
            "x": 0,
            "y": 1,
            "z": 43,
            "elements": [
                "nuclearcraft:electromagnet_supercooler_active@0"
            ]
        },
        {
            "x": -50,
            "y": 0,
            "z": 9,
            "elements": [
                "nuclearcraft:accelerator_electromagnet_active@0"
            ]
        },
        {
            "x": -50,
            "y": -1,
            "z": 41,
            "elements": [
                "nuclearcraft:electromagnet_supercooler_active@0"
            ]
        },
        {
            "x": -2,
            "y": 0,
            "z": 26,
            "elements": [
                "nuclearcraft:accelerator_electromagnet_active@0"
            ]
        },
        {
            "x": -49,
            "y": -1,
            "z": 41,
            "elements": [
                "nuclearcraft:accelerator_electromagnet_active@0"
            ]
        },
        {
            "x": -48,
            "y": 0,
            "z": 9,
            "elements": [
                "nuclearcraft:accelerator_electromagnet_active@0"
            ]
        },
        {
            "x": -48,
            "y": -1,
            "z": 41,
            "elements": [
                "nuclearcraft:electromagnet_supercooler_active@0"
            ]
        },
        {
            "x": 0,
            "y": 0,
            "z": 26,
            "elements": [
                "nuclearcraft:accelerator_electromagnet_active@0"
            ]
        },
        {
            "x": -2,
            "y": -1,
            "z": 9,
            "elements": [
                "nuclearcraft:electromagnet_supercooler_active@0"
            ]
        },
        {
            "x": -1,
            "y": -1,
            "z": 9,
            "elements": [
                "nuclearcraft:accelerator_electromagnet_active@0"
            ]
        },
        {
            "x": 0,
            "y": -1,
            "z": 9,
            "elements": [
                "nuclearcraft:electromagnet_supercooler_active@0"
            ]
        },
        {
            "x": -50,
            "y": 1,
            "z": 9,
            "elements": [
                "nuclearcraft:electromagnet_supercooler_active@0"
            ]
        },
        {
            "x": -50,
            "y": 0,
            "z": 41,
            "elements": [
                "nuclearcraft:accelerator_electromagnet_active@0"
            ]
        },
        {
            "x": -2,
            "y": 1,
            "z": 26,
            "elements": [
                "nuclearcraft:electromagnet_supercooler_active@0"
            ]
        },
        {
            "x": -49,
            "y": 1,
            "z": 9,
            "elements": [
                "nuclearcraft:accelerator_electromagnet_active@0"
            ]
        },
        {
            "x": -1,
            "y": 1,
            "z": 26,
            "elements": [
                "nuclearcraft:accelerator_electromagnet_active@0"
            ]
        },
        {
            "x": -48,
            "y": 1,
            "z": 9,
            "elements": [
                "nuclearcraft:electromagnet_supercooler_active@0"
            ]
        },
        {
            "x": -48,
            "y": 0,
            "z": 41,
            "elements": [
                "nuclearcraft:accelerator_electromagnet_active@0"
            ]
        },
        {
            "x": 0,
            "y": 1,
            "z": 26,
            "elements": [
                "nuclearcraft:electromagnet_supercooler_active@0"
            ]
        },
        {
            "x": -50,
            "y": -1,
            "z": 24,
            "elements": [
                "nuclearcraft:electromagnet_supercooler_active@0"
            ]
        },
        {
            "x": -2,
            "y": 0,
            "z": 9,
            "elements": [
                "nuclearcraft:accelerator_electromagnet_active@0"
            ]
        },
        {
            "x": -2,
            "y": -1,
            "z": 41,
            "elements": [
                "nuclearcraft:electromagnet_supercooler_active@0"
            ]
        },
        {
            "x": -49,
            "y": -1,
            "z": 24,
            "elements": [
                "nuclearcraft:accelerator_electromagnet_active@0"
            ]
        },
        {
            "x": -1,
            "y": -1,
            "z": 41,
            "elements": [
                "nuclearcraft:accelerator_electromagnet_active@0"
            ]
        },
        {
            "x": -48,
            "y": -1,
            "z": 24,
            "elements": [
                "nuclearcraft:electromagnet_supercooler_active@0"
            ]
        },
        {
            "x": 0,
            "y": 0,
            "z": 9,
            "elements": [
                "nuclearcraft:accelerator_electromagnet_active@0"
            ]
        },
        {
            "x": 0,
            "y": -1,
            "z": 41,
            "elements": [
                "nuclearcraft:electromagnet_supercooler_active@0"
            ]
        },
        {
            "x": -50,
            "y": 1,
            "z": 41,
            "elements": [
                "nuclearcraft:electromagnet_supercooler_active@0"
            ]
        },
        {
            "x": -49,
            "y": 1,
            "z": 41,
            "elements": [
                "nuclearcraft:accelerator_electromagnet_active@0"
            ]
        },
        {
            "x": -48,
            "y": 1,
            "z": 41,
            "elements": [
                "nuclearcraft:electromagnet_supercooler_active@0"
            ]
        },
        {
            "x": -50,
            "y": 0,
            "z": 24,
            "elements": [
                "nuclearcraft:accelerator_electromagnet_active@0"
            ]
        },
        {
            "x": -2,
            "y": 1,
            "z": 9,
            "elements": [
                "nuclearcraft:electromagnet_supercooler_active@0"
            ]
        },
        {
            "x": -2,
            "y": 0,
            "z": 41,
            "elements": [
                "nuclearcraft:accelerator_electromagnet_active@0"
            ]
        },
        {
            "x": -1,
            "y": 1,
            "z": 9,
            "elements": [
                "nuclearcraft:accelerator_electromagnet_active@0"
            ]
        },
        {
            "x": -48,
            "y": 0,
            "z": 24,
            "elements": [
                "nuclearcraft:accelerator_electromagnet_active@0"
            ]
        },
        {
            "x": 0,
            "y": 1,
            "z": 9,
            "elements": [
                "nuclearcraft:electromagnet_supercooler_active@0"
            ]
        },
        {
            "x": 0,
            "y": 0,
            "z": 41,
            "elements": [
                "nuclearcraft:accelerator_electromagnet_active@0"
            ]
        },
        {
            "x": -50,
            "y": -1,
            "z": 7,
            "elements": [
                "nuclearcraft:electromagnet_supercooler_active@0"
            ]
        },
        {
            "x": -2,
            "y": -1,
            "z": 24,
            "elements": [
                "nuclearcraft:electromagnet_supercooler_active@0"
            ]
        },
        {
            "x": -49,
            "y": -1,
            "z": 7,
            "elements": [
                "nuclearcraft:accelerator_electromagnet_active@0"
            ]
        },
        {
            "x": -1,
            "y": -1,
            "z": 24,
            "elements": [
                "nuclearcraft:accelerator_electromagnet_active@0"
            ]
        },
        {
            "x": -48,
            "y": -1,
            "z": 7,
            "elements": [
                "nuclearcraft:electromagnet_supercooler_active@0"
            ]
        },
        {
            "x": 0,
            "y": -1,
            "z": 24,
            "elements": [
                "nuclearcraft:electromagnet_supercooler_active@0"
            ]
        },
        {
            "x": -50,
            "y": 1,
            "z": 24,
            "elements": [
                "nuclearcraft:electromagnet_supercooler_active@0"
            ]
        },
        {
            "x": -2,
            "y": 1,
            "z": 41,
            "elements": [
                "nuclearcraft:electromagnet_supercooler_active@0"
            ]
        },
        {
            "x": -49,
            "y": 1,
            "z": 24,
            "elements": [
                "nuclearcraft:accelerator_electromagnet_active@0"
            ]
        },
        {
            "x": -1,
            "y": 1,
            "z": 41,
            "elements": [
                "nuclearcraft:accelerator_electromagnet_active@0"
            ]
        },
        {
            "x": -48,
            "y": 1,
            "z": 24,
            "elements": [
                "nuclearcraft:electromagnet_supercooler_active@0"
            ]
        },
        {
            "x": 0,
            "y": 1,
            "z": 41,
            "elements": [
                "nuclearcraft:electromagnet_supercooler_active@0"
            ]
        },
        {
            "x": -50,
            "y": 0,
            "z": 7,
            "elements": [
                "nuclearcraft:accelerator_electromagnet_active@0"
            ]
        },
        {
            "x": -50,
            "y": -1,
            "z": 39,
            "elements": [
                "nuclearcraft:electromagnet_supercooler_active@0"
            ]
        },
        {
            "x": -2,
            "y": 0,
            "z": 24,
            "elements": [
                "nuclearcraft:accelerator_electromagnet_active@0"
            ]
        },
        {
            "x": -49,
            "y": -1,
            "z": 39,
            "elements": [
                "nuclearcraft:accelerator_electromagnet_active@0"
            ]
        },
        {
            "x": -48,
            "y": 0,
            "z": 7,
            "elements": [
                "nuclearcraft:accelerator_electromagnet_active@0"
            ]
        },
        {
            "x": -48,
            "y": -1,
            "z": 39,
            "elements": [
                "nuclearcraft:electromagnet_supercooler_active@0"
            ]
        },
        {
            "x": 0,
            "y": 0,
            "z": 24,
            "elements": [
                "nuclearcraft:accelerator_electromagnet_active@0"
            ]
        },
        {
            "x": -2,
            "y": -1,
            "z": 7,
            "elements": [
                "nuclearcraft:electromagnet_supercooler_active@0"
            ]
        },
        {
            "x": -1,
            "y": -1,
            "z": 7,
            "elements": [
                "nuclearcraft:accelerator_electromagnet_active@0"
            ]
        },
        {
            "x": 0,
            "y": -1,
            "z": 7,
            "elements": [
                "nuclearcraft:electromagnet_supercooler_active@0"
            ]
        },
        {
            "x": -50,
            "y": 1,
            "z": 7,
            "elements": [
                "nuclearcraft:electromagnet_supercooler_active@0"
            ]
        },
        {
            "x": -50,
            "y": 0,
            "z": 39,
            "elements": [
                "nuclearcraft:accelerator_electromagnet_active@0"
            ]
        },
        {
            "x": -2,
            "y": 1,
            "z": 24,
            "elements": [
                "nuclearcraft:electromagnet_supercooler_active@0"
            ]
        },
        {
            "x": -49,
            "y": 1,
            "z": 7,
            "elements": [
                "nuclearcraft:accelerator_electromagnet_active@0"
            ]
        },
        {
            "x": -1,
            "y": 1,
            "z": 24,
            "elements": [
                "nuclearcraft:accelerator_electromagnet_active@0"
            ]
        },
        {
            "x": -48,
            "y": 1,
            "z": 7,
            "elements": [
                "nuclearcraft:electromagnet_supercooler_active@0"
            ]
        },
        {
            "x": -48,
            "y": 0,
            "z": 39,
            "elements": [
                "nuclearcraft:accelerator_electromagnet_active@0"
            ]
        },
        {
            "x": 0,
            "y": 1,
            "z": 24,
            "elements": [
                "nuclearcraft:electromagnet_supercooler_active@0"
            ]
        },
        {
            "x": -50,
            "y": -1,
            "z": 22,
            "elements": [
                "nuclearcraft:electromagnet_supercooler_active@0"
            ]
        },
        {
            "x": -2,
            "y": 0,
            "z": 7,
            "elements": [
                "nuclearcraft:accelerator_electromagnet_active@0"
            ]
        },
        {
            "x": -2,
            "y": -1,
            "z": 39,
            "elements": [
                "nuclearcraft:electromagnet_supercooler_active@0"
            ]
        },
        {
            "x": -49,
            "y": -1,
            "z": 22,
            "elements": [
                "nuclearcraft:accelerator_electromagnet_active@0"
            ]
        },
        {
            "x": -1,
            "y": -1,
            "z": 39,
            "elements": [
                "nuclearcraft:accelerator_electromagnet_active@0"
            ]
        },
        {
            "x": -48,
            "y": -1,
            "z": 22,
            "elements": [
                "nuclearcraft:electromagnet_supercooler_active@0"
            ]
        },
        {
            "x": 0,
            "y": 0,
            "z": 7,
            "elements": [
                "nuclearcraft:accelerator_electromagnet_active@0"
            ]
        },
        {
            "x": 0,
            "y": -1,
            "z": 39,
            "elements": [
                "nuclearcraft:electromagnet_supercooler_active@0"
            ]
        },
        {
            "x": -50,
            "y": 1,
            "z": 39,
            "elements": [
                "nuclearcraft:electromagnet_supercooler_active@0"
            ]
        },
        {
            "x": -49,
            "y": 1,
            "z": 39,
            "elements": [
                "nuclearcraft:accelerator_electromagnet_active@0"
            ]
        },
        {
            "x": -48,
            "y": 1,
            "z": 39,
            "elements": [
                "nuclearcraft:electromagnet_supercooler_active@0"
            ]
        },
        {
            "x": -50,
            "y": 0,
            "z": 22,
            "elements": [
                "nuclearcraft:accelerator_electromagnet_active@0"
            ]
        },
        {
            "x": -2,
            "y": 1,
            "z": 7,
            "elements": [
                "nuclearcraft:electromagnet_supercooler_active@0"
            ]
        },
        {
            "x": -2,
            "y": 0,
            "z": 39,
            "elements": [
                "nuclearcraft:accelerator_electromagnet_active@0"
            ]
        },
        {
            "x": -1,
            "y": 1,
            "z": 7,
            "elements": [
                "nuclearcraft:accelerator_electromagnet_active@0"
            ]
        },
        {
            "x": -48,
            "y": 0,
            "z": 22,
            "elements": [
                "nuclearcraft:accelerator_electromagnet_active@0"
            ]
        },
        {
            "x": 0,
            "y": 1,
            "z": 7,
            "elements": [
                "nuclearcraft:electromagnet_supercooler_active@0"
            ]
        },
        {
            "x": 0,
            "y": 0,
            "z": 39,
            "elements": [
                "nuclearcraft:accelerator_electromagnet_active@0"
            ]
        },
        {
            "x": -50,
            "y": -1,
            "z": 5,
            "elements": [
                "nuclearcraft:electromagnet_supercooler_active@0"
            ]
        },
        {
            "x": -2,
            "y": -1,
            "z": 22,
            "elements": [
                "nuclearcraft:electromagnet_supercooler_active@0"
            ]
        },
        {
            "x": -49,
            "y": -1,
            "z": 5,
            "elements": [
                "nuclearcraft:accelerator_electromagnet_active@0"
            ]
        },
        {
            "x": -1,
            "y": -1,
            "z": 22,
            "elements": [
                "nuclearcraft:accelerator_electromagnet_active@0"
            ]
        },
        {
            "x": -48,
            "y": -1,
            "z": 5,
            "elements": [
                "nuclearcraft:electromagnet_supercooler_active@0"
            ]
        },
        {
            "x": 0,
            "y": -1,
            "z": 22,
            "elements": [
                "nuclearcraft:electromagnet_supercooler_active@0"
            ]
        },
        {
            "x": -50,
            "y": 1,
            "z": 22,
            "elements": [
                "nuclearcraft:electromagnet_supercooler_active@0"
            ]
        },
        {
            "x": -2,
            "y": 1,
            "z": 39,
            "elements": [
                "nuclearcraft:electromagnet_supercooler_active@0"
            ]
        },
        {
            "x": -49,
            "y": 1,
            "z": 22,
            "elements": [
                "nuclearcraft:accelerator_electromagnet_active@0"
            ]
        },
        {
            "x": -1,
            "y": 1,
            "z": 39,
            "elements": [
                "nuclearcraft:accelerator_electromagnet_active@0"
            ]
        },
        {
            "x": -48,
            "y": 1,
            "z": 22,
            "elements": [
                "nuclearcraft:electromagnet_supercooler_active@0"
            ]
        },
        {
            "x": 0,
            "y": 1,
            "z": 39,
            "elements": [
                "nuclearcraft:electromagnet_supercooler_active@0"
            ]
        },
        {
            "x": -50,
            "y": 0,
            "z": 5,
            "elements": [
                "nuclearcraft:accelerator_electromagnet_active@0"
            ]
        },
        {
            "x": -50,
            "y": -1,
            "z": 37,
            "elements": [
                "nuclearcraft:electromagnet_supercooler_active@0"
            ]
        },
        {
            "x": -2,
            "y": 0,
            "z": 22,
            "elements": [
                "nuclearcraft:accelerator_electromagnet_active@0"
            ]
        },
        {
            "x": -49,
            "y": -1,
            "z": 37,
            "elements": [
                "nuclearcraft:accelerator_electromagnet_active@0"
            ]
        },
        {
            "x": -48,
            "y": 0,
            "z": 5,
            "elements": [
                "nuclearcraft:accelerator_electromagnet_active@0"
            ]
        },
        {
            "x": -48,
            "y": -1,
            "z": 37,
            "elements": [
                "nuclearcraft:electromagnet_supercooler_active@0"
            ]
        },
        {
            "x": 0,
            "y": 0,
            "z": 22,
            "elements": [
                "nuclearcraft:accelerator_electromagnet_active@0"
            ]
        },
        {
            "x": -2,
            "y": -1,
            "z": 5,
            "elements": [
                "nuclearcraft:electromagnet_supercooler_active@0"
            ]
        },
        {
            "x": -1,
            "y": -1,
            "z": 5,
            "elements": [
                "nuclearcraft:accelerator_electromagnet_active@0"
            ]
        },
        {
            "x": 0,
            "y": -1,
            "z": 5,
            "elements": [
                "nuclearcraft:electromagnet_supercooler_active@0"
            ]
        },
        {
            "x": -50,
            "y": 1,
            "z": 5,
            "elements": [
                "nuclearcraft:electromagnet_supercooler_active@0"
            ]
        },
        {
            "x": -50,
            "y": 0,
            "z": 37,
            "elements": [
                "nuclearcraft:accelerator_electromagnet_active@0"
            ]
        },
        {
            "x": -2,
            "y": 1,
            "z": 22,
            "elements": [
                "nuclearcraft:electromagnet_supercooler_active@0"
            ]
        },
        {
            "x": -49,
            "y": 1,
            "z": 5,
            "elements": [
                "nuclearcraft:accelerator_electromagnet_active@0"
            ]
        },
        {
            "x": -1,
            "y": 1,
            "z": 22,
            "elements": [
                "nuclearcraft:accelerator_electromagnet_active@0"
            ]
        },
        {
            "x": -48,
            "y": 1,
            "z": 5,
            "elements": [
                "nuclearcraft:electromagnet_supercooler_active@0"
            ]
        },
        {
            "x": -48,
            "y": 0,
            "z": 37,
            "elements": [
                "nuclearcraft:accelerator_electromagnet_active@0"
            ]
        },
        {
            "x": 0,
            "y": 1,
            "z": 22,
            "elements": [
                "nuclearcraft:electromagnet_supercooler_active@0"
            ]
        },
        {
            "x": -50,
            "y": -1,
            "z": 20,
            "elements": [
                "nuclearcraft:electromagnet_supercooler_active@0"
            ]
        },
        {
            "x": -2,
            "y": 0,
            "z": 5,
            "elements": [
                "nuclearcraft:accelerator_electromagnet_active@0"
            ]
        },
        {
            "x": -2,
            "y": -1,
            "z": 37,
            "elements": [
                "nuclearcraft:electromagnet_supercooler_active@0"
            ]
        },
        {
            "x": -49,
            "y": -1,
            "z": 20,
            "elements": [
                "nuclearcraft:accelerator_electromagnet_active@0"
            ]
        },
        {
            "x": -1,
            "y": -1,
            "z": 37,
            "elements": [
                "nuclearcraft:accelerator_electromagnet_active@0"
            ]
        },
        {
            "x": -48,
            "y": -1,
            "z": 20,
            "elements": [
                "nuclearcraft:electromagnet_supercooler_active@0"
            ]
        },
        {
            "x": 0,
            "y": 0,
            "z": 5,
            "elements": [
                "nuclearcraft:accelerator_electromagnet_active@0"
            ]
        },
        {
            "x": 0,
            "y": -1,
            "z": 37,
            "elements": [
                "nuclearcraft:electromagnet_supercooler_active@0"
            ]
        },
        {
            "x": -50,
            "y": 1,
            "z": 37,
            "elements": [
                "nuclearcraft:electromagnet_supercooler_active@0"
            ]
        },
        {
            "x": -49,
            "y": 1,
            "z": 37,
            "elements": [
                "nuclearcraft:accelerator_electromagnet_active@0"
            ]
        },
        {
            "x": -48,
            "y": 1,
            "z": 37,
            "elements": [
                "nuclearcraft:electromagnet_supercooler_active@0"
            ]
        },
        {
            "x": -50,
            "y": 0,
            "z": 20,
            "elements": [
                "nuclearcraft:accelerator_electromagnet_active@0"
            ]
        },
        {
            "x": -2,
            "y": 1,
            "z": 5,
            "elements": [
                "nuclearcraft:electromagnet_supercooler_active@0"
            ]
        },
        {
            "x": -2,
            "y": 0,
            "z": 37,
            "elements": [
                "nuclearcraft:accelerator_electromagnet_active@0"
            ]
        },
        {
            "x": -1,
            "y": 1,
            "z": 5,
            "elements": [
                "nuclearcraft:accelerator_electromagnet_active@0"
            ]
        },
        {
            "x": -48,
            "y": 0,
            "z": 20,
            "elements": [
                "nuclearcraft:accelerator_electromagnet_active@0"
            ]
        },
        {
            "x": 0,
            "y": 1,
            "z": 5,
            "elements": [
                "nuclearcraft:electromagnet_supercooler_active@0"
            ]
        },
        {
            "x": 0,
            "y": 0,
            "z": 37,
            "elements": [
                "nuclearcraft:accelerator_electromagnet_active@0"
            ]
        },
        {
            "x": -50,
            "y": -1,
            "z": 3,
            "elements": [
                "nuclearcraft:electromagnet_supercooler_active@0"
            ]
        },
        {
            "x": -2,
            "y": -1,
            "z": 20,
            "elements": [
                "nuclearcraft:electromagnet_supercooler_active@0"
            ]
        },
        {
            "x": -49,
            "y": -1,
            "z": 3,
            "elements": [
                "nuclearcraft:accelerator_electromagnet_active@0"
            ]
        },
        {
            "x": -1,
            "y": -1,
            "z": 20,
            "elements": [
                "nuclearcraft:accelerator_electromagnet_active@0"
            ]
        },
        {
            "x": -48,
            "y": -1,
            "z": 3,
            "elements": [
                "nuclearcraft:electromagnet_supercooler_active@0"
            ]
        },
        {
            "x": 0,
            "y": -1,
            "z": 20,
            "elements": [
                "nuclearcraft:electromagnet_supercooler_active@0"
            ]
        },
        {
            "x": -50,
            "y": 1,
            "z": 20,
            "elements": [
                "nuclearcraft:electromagnet_supercooler_active@0"
            ]
        },
        {
            "x": -2,
            "y": 1,
            "z": 37,
            "elements": [
                "nuclearcraft:electromagnet_supercooler_active@0"
            ]
        },
        {
            "x": -49,
            "y": 1,
            "z": 20,
            "elements": [
                "nuclearcraft:accelerator_electromagnet_active@0"
            ]
        },
        {
            "x": -1,
            "y": 1,
            "z": 37,
            "elements": [
                "nuclearcraft:accelerator_electromagnet_active@0"
            ]
        },
        {
            "x": -48,
            "y": 1,
            "z": 20,
            "elements": [
                "nuclearcraft:electromagnet_supercooler_active@0"
            ]
        },
        {
            "x": 0,
            "y": 1,
            "z": 37,
            "elements": [
                "nuclearcraft:electromagnet_supercooler_active@0"
            ]
        },
        {
            "x": -50,
            "y": 0,
            "z": 3,
            "elements": [
                "nuclearcraft:accelerator_electromagnet_active@0"
            ]
        },
        {
            "x": -50,
            "y": -1,
            "z": 35,
            "elements": [
                "nuclearcraft:electromagnet_supercooler_active@0"
            ]
        },
        {
            "x": -2,
            "y": 0,
            "z": 20,
            "elements": [
                "nuclearcraft:accelerator_electromagnet_active@0"
            ]
        },
        {
            "x": -49,
            "y": -1,
            "z": 35,
            "elements": [
                "nuclearcraft:accelerator_electromagnet_active@0"
            ]
        },
        {
            "x": -48,
            "y": 0,
            "z": 3,
            "elements": [
                "nuclearcraft:accelerator_electromagnet_active@0"
            ]
        },
        {
            "x": -48,
            "y": -1,
            "z": 35,
            "elements": [
                "nuclearcraft:electromagnet_supercooler_active@0"
            ]
        },
        {
            "x": 0,
            "y": 0,
            "z": 20,
            "elements": [
                "nuclearcraft:accelerator_electromagnet_active@0"
            ]
        },
        {
            "x": -2,
            "y": -1,
            "z": 3,
            "elements": [
                "nuclearcraft:electromagnet_supercooler_active@0"
            ]
        },
        {
            "x": -1,
            "y": -1,
            "z": 3,
            "elements": [
                "nuclearcraft:accelerator_electromagnet_active@0"
            ]
        },
        {
            "x": 0,
            "y": -1,
            "z": 3,
            "elements": [
                "nuclearcraft:electromagnet_supercooler_active@0"
            ]
        },
        {
            "x": -50,
            "y": 1,
            "z": 3,
            "elements": [
                "nuclearcraft:electromagnet_supercooler_active@0"
            ]
        },
        {
            "x": -50,
            "y": 0,
            "z": 35,
            "elements": [
                "nuclearcraft:accelerator_electromagnet_active@0"
            ]
        },
        {
            "x": -2,
            "y": 1,
            "z": 20,
            "elements": [
                "nuclearcraft:electromagnet_supercooler_active@0"
            ]
        },
        {
            "x": -49,
            "y": 1,
            "z": 3,
            "elements": [
                "nuclearcraft:accelerator_electromagnet_active@0"
            ]
        },
        {
            "x": -1,
            "y": 1,
            "z": 20,
            "elements": [
                "nuclearcraft:accelerator_electromagnet_active@0"
            ]
        },
        {
            "x": -48,
            "y": 1,
            "z": 3,
            "elements": [
                "nuclearcraft:electromagnet_supercooler_active@0"
            ]
        },
        {
            "x": -48,
            "y": 0,
            "z": 35,
            "elements": [
                "nuclearcraft:accelerator_electromagnet_active@0"
            ]
        },
        {
            "x": 0,
            "y": 1,
            "z": 20,
            "elements": [
                "nuclearcraft:electromagnet_supercooler_active@0"
            ]
        },
        {
            "x": -50,
            "y": -1,
            "z": 18,
            "elements": [
                "nuclearcraft:electromagnet_supercooler_active@0"
            ]
        },
        {
            "x": -2,
            "y": 0,
            "z": 3,
            "elements": [
                "nuclearcraft:accelerator_electromagnet_active@0"
            ]
        },
        {
            "x": -2,
            "y": -1,
            "z": 35,
            "elements": [
                "nuclearcraft:electromagnet_supercooler_active@0"
            ]
        },
        {
            "x": -49,
            "y": -1,
            "z": 18,
            "elements": [
                "nuclearcraft:accelerator_electromagnet_active@0"
            ]
        },
        {
            "x": -1,
            "y": -1,
            "z": 35,
            "elements": [
                "nuclearcraft:accelerator_electromagnet_active@0"
            ]
        },
        {
            "x": -48,
            "y": -1,
            "z": 18,
            "elements": [
                "nuclearcraft:electromagnet_supercooler_active@0"
            ]
        },
        {
            "x": 0,
            "y": 0,
            "z": 3,
            "elements": [
                "nuclearcraft:accelerator_electromagnet_active@0"
            ]
        },
        {
            "x": 0,
            "y": -1,
            "z": 35,
            "elements": [
                "nuclearcraft:electromagnet_supercooler_active@0"
            ]
        },
        {
            "x": -50,
            "y": 1,
            "z": 35,
            "elements": [
                "nuclearcraft:electromagnet_supercooler_active@0"
            ]
        },
        {
            "x": -49,
            "y": 1,
            "z": 35,
            "elements": [
                "nuclearcraft:accelerator_electromagnet_active@0"
            ]
        },
        {
            "x": -48,
            "y": 1,
            "z": 35,
            "elements": [
                "nuclearcraft:electromagnet_supercooler_active@0"
            ]
        },
        {
            "x": -50,
            "y": 0,
            "z": 18,
            "elements": [
                "nuclearcraft:accelerator_electromagnet_active@0"
            ]
        },
        {
            "x": -2,
            "y": 1,
            "z": 3,
            "elements": [
                "nuclearcraft:electromagnet_supercooler_active@0"
            ]
        },
        {
            "x": -50,
            "y": -1,
            "z": 50,
            "elements": [
                "nuclearcraft:electromagnet_supercooler_active@0"
            ]
        },
        {
            "x": -2,
            "y": 0,
            "z": 35,
            "elements": [
                "nuclearcraft:accelerator_electromagnet_active@0"
            ]
        },
        {
            "x": -1,
            "y": 1,
            "z": 3,
            "elements": [
                "nuclearcraft:accelerator_electromagnet_active@0"
            ]
        },
        {
            "x": -49,
            "y": -1,
            "z": 50,
            "elements": [
                "nuclearcraft:electromagnet_supercooler_active@0"
            ]
        },
        {
            "x": -48,
            "y": 0,
            "z": 18,
            "elements": [
                "nuclearcraft:accelerator_electromagnet_active@0"
            ]
        },
        {
            "x": 0,
            "y": 1,
            "z": 3,
            "elements": [
                "nuclearcraft:electromagnet_supercooler_active@0"
            ]
        },
        {
            "x": -48,
            "y": -1,
            "z": 50,
            "elements": [
                "nuclearcraft:electromagnet_supercooler_active@0"
            ]
        },
        {
            "x": 0,
            "y": 0,
            "z": 35,
            "elements": [
                "nuclearcraft:accelerator_electromagnet_active@0"
            ]
        },
        {
            "x": -47,
            "y": -1,
            "z": 50,
            "elements": [
                "nuclearcraft:electromagnet_supercooler_active@0"
            ]
        },
        {
            "x": -46,
            "y": -1,
            "z": 50,
            "elements": [
                "nuclearcraft:electromagnet_supercooler_active@0"
            ]
        },
        {
            "x": -45,
            "y": -1,
            "z": 50,
            "elements": [
                "nuclearcraft:electromagnet_supercooler_active@0"
            ]
        },
        {
            "x": -44,
            "y": -1,
            "z": 50,
            "elements": [
                "nuclearcraft:electromagnet_supercooler_active@0"
            ]
        },
        {
            "x": -43,
            "y": -1,
            "z": 50,
            "elements": [
                "nuclearcraft:electromagnet_supercooler_active@0"
            ]
        },
        {
            "x": -42,
            "y": -1,
            "z": 50,
            "elements": [
                "nuclearcraft:electromagnet_supercooler_active@0"
            ]
        },
        {
            "x": -41,
            "y": -1,
            "z": 50,
            "elements": [
                "nuclearcraft:electromagnet_supercooler_active@0"
            ]
        },
        {
            "x": -40,
            "y": -1,
            "z": 50,
            "elements": [
                "nuclearcraft:electromagnet_supercooler_active@0"
            ]
        },
        {
            "x": -39,
            "y": -1,
            "z": 50,
            "elements": [
                "nuclearcraft:electromagnet_supercooler_active@0"
            ]
        },
        {
            "x": -38,
            "y": -1,
            "z": 50,
            "elements": [
                "nuclearcraft:electromagnet_supercooler_active@0"
            ]
        },
        {
            "x": -37,
            "y": -1,
            "z": 50,
            "elements": [
                "nuclearcraft:electromagnet_supercooler_active@0"
            ]
        },
        {
            "x": -36,
            "y": -1,
            "z": 50,
            "elements": [
                "nuclearcraft:electromagnet_supercooler_active@0"
            ]
        },
        {
            "x": -35,
            "y": -1,
            "z": 50,
            "elements": [
                "nuclearcraft:electromagnet_supercooler_active@0"
            ]
        },
        {
            "x": -50,
            "y": -1,
            "z": 1,
            "elements": [
                "nuclearcraft:electromagnet_supercooler_active@0"
            ]
        },
        {
            "x": -34,
            "y": -1,
            "z": 50,
            "elements": [
                "nuclearcraft:electromagnet_supercooler_active@0"
            ]
        },
        {
            "x": -2,
            "y": -1,
            "z": 18,
            "elements": [
                "nuclearcraft:electromagnet_supercooler_active@0"
            ]
        },
        {
            "x": -49,
            "y": -1,
            "z": 1,
            "elements": [
                "nuclearcraft:accelerator_electromagnet_active@0"
            ]
        },
        {
            "x": -33,
            "y": -1,
            "z": 50,
            "elements": [
                "nuclearcraft:electromagnet_supercooler_active@0"
            ]
        },
        {
            "x": -1,
            "y": -1,
            "z": 18,
            "elements": [
                "nuclearcraft:accelerator_electromagnet_active@0"
            ]
        },
        {
            "x": -48,
            "y": -1,
            "z": 1,
            "elements": [
                "nuclearcraft:accelerator_electromagnet_active@0"
            ]
        },
        {
            "x": -32,
            "y": -1,
            "z": 50,
            "elements": [
                "nuclearcraft:electromagnet_supercooler_active@0"
            ]
        },
        {
            "x": 0,
            "y": -1,
            "z": 18,
            "elements": [
                "nuclearcraft:electromagnet_supercooler_active@0"
            ]
        },
        {
            "x": -47,
            "y": -1,
            "z": 1,
            "elements": [
