{
    "registryname": "medium_particle_accelerator",
    "localizedname": "Medium Particle Accelerator",
    "modifiers": [
        {
            "elements": "modularmachinery:blockinputbus",
            "x": 0,
            "y": 0,
            "z": 1,
            "description": "Replace fluid input with item input\nto rip apart matter instead of\ncreating exotic matter",
            "modifier": {
                "target": "modularmachinery:item",
                "io": "input",
                "operation": 1,
                "multiplier": 1.0
            }
        }
    ],
    "parts": [
        {
            "x": -1,
            "y": 0,
            "z": 0,
            "elements": [
                "modularmachinery:blockoutputbus"
            ]
        },
        {
            "x": -2,
            "y": 0,
            "z": 0,
            "elements": [
                "nuclearcraft:accelerator_electromagnet_active@0"
            ]
        },
        {
            "x": -3,
            "y": 0,
            "z": 0,
            "elements": [
                "nuclearcraft:accelerator_electromagnet_active@0"
            ]
        },
        {
            "x": -4,
            "y": 0,
            "z": 0,
            "elements": [
                "nuclearcraft:accelerator_electromagnet_active@0"
            ]
        },
        {
            "x": -5,
            "y": 0,
            "z": 0,
            "elements": [
                "nuclearcraft:accelerator_electromagnet_active@0"
            ]
        },
        {
            "x": -6,
            "y": 0,
            "z": 0,
            "elements": [
                "nuclearcraft:accelerator_electromagnet_active@0"
            ]
        },
        {
            "x": -7,
            "y": 0,
            "z": 0,
            "elements": [
                "nuclearcraft:accelerator_electromagnet_active@0"
            ]
        },
        {
            "x": -8,
            "y": 0,
            "z": 0,
            "elements": [
                "nuclearcraft:accelerator_electromagnet_active@0"
            ]
        },
        {
            "x": -9,
            "y": 0,
            "z": 0,
            "elements": [
                "nuclearcraft:accelerator_electromagnet_active@0"
            ]
        },
        {
            "x": -10,
            "y": 0,
            "z": 0,
            "elements": [
                "nuclearcraft:accelerator_electromagnet_active@0"
            ]
        },
        {
            "x": -11,
            "y": 0,
            "z": 0,
            "elements": [
                "nuclearcraft:accelerator_electromagnet_active@0"
            ]
        },
        {
            "x": -20,
            "y": 1,
            "z": 0,
            "elements": [
                "nuclearcraft:electromagnet_supercooler_active@0"
            ]
        },
        {
            "x": -12,
            "y": 0,
            "z": 0,
            "elements": [
                "nuclearcraft:accelerator_electromagnet_active@0"
            ]
        },
        {
            "x": -19,
            "y": 1,
            "z": 0,
            "elements": [
                "nuclearcraft:electromagnet_supercooler_active@0"
            ]
        },
        {
            "x": -13,
            "y": 0,
            "z": 0,
            "elements": [
                "nuclearcraft:accelerator_electromagnet_active@0"
            ]
        },
        {
            "x": -18,
            "y": 1,
            "z": 0,
            "elements": [
                "nuclearcraft:electromagnet_supercooler_active@0"
            ]
        },
        {
            "x": -14,
            "y": 0,
            "z": 0,
            "elements": [
                "nuclearcraft:accelerator_electromagnet_active@0"
            ]
        },
        {
            "x": -17,
            "y": 1,
            "z": 0,
            "elements": [
                "nuclearcraft:electromagnet_supercooler_active@0"
            ]
        },
        {
            "x": -15,
            "y": 0,
            "z": 0,
            "elements": [
                "nuclearcraft:accelerator_electromagnet_active@0"
            ]
        },
        {
            "x": -2,
            "y": 0,
            "z": 16,
            "elements": [
                "nuclearcraft:accelerator_electromagnet_active@0"
            ]
        },
        {
            "x": -16,
            "y": 0,
            "z": 0,
            "elements": [
                "nuclearcraft:accelerator_electromagnet_active@0"
            ]
        },
        {
            "x": -16,
            "y": 1,
            "z": 0,
            "elements": [
                "nuclearcraft:electromagnet_supercooler_active@0"
            ]
        },
        {
            "x": 0,
            "y": 0,
            "z": 16,
            "elements": [
                "nuclearcraft:accelerator_electromagnet_active@0"
            ]
        },
        {
            "x": -17,
            "y": 0,
            "z": 0,
            "elements": [
                "nuclearcraft:accelerator_electromagnet_active@0"
            ]
        },
        {
            "x": -15,
            "y": 1,
            "z": 0,
            "elements": [
                "nuclearcraft:electromagnet_supercooler_active@0"
            ]
        },
        {
            "x": -18,
            "y": 0,
            "z": 0,
            "elements": [
                "nuclearcraft:accelerator_electromagnet_active@0"
            ]
        },
        {
            "x": -14,
            "y": 1,
            "z": 0,
            "elements": [
                "nuclearcraft:electromagnet_supercooler_active@0"
            ]
        },
        {
            "x": -19,
            "y": 0,
            "z": 0,
            "elements": [
                "nuclearcraft:accelerator_electromagnet_active@0"
            ]
        },
        {
            "x": -13,
            "y": 1,
            "z": 0,
            "elements": [
                "nuclearcraft:electromagnet_supercooler_active@0"
            ]
        },
        {
            "x": -20,
            "y": 0,
            "z": 0,
            "elements": [
                "nuclearcraft:accelerator_electromagnet_active@0"
            ]
        },
        {
            "x": -12,
            "y": 1,
            "z": 0,
            "elements": [
                "nuclearcraft:electromagnet_supercooler_active@0"
            ]
        },
        {
            "x": -11,
            "y": 1,
            "z": 0,
            "elements": [
                "nuclearcraft:electromagnet_supercooler_active@0"
            ]
        },
        {
            "x": -10,
            "y": 1,
            "z": 0,
            "elements": [
                "nuclearcraft:electromagnet_supercooler_active@0"
            ]
        },
        {
            "x": -9,
            "y": 1,
            "z": 0,
            "elements": [
                "nuclearcraft:electromagnet_supercooler_active@0"
            ]
        },
        {
            "x": -8,
            "y": 1,
            "z": 0,
            "elements": [
                "nuclearcraft:electromagnet_supercooler_active@0"
            ]
        },
        {
            "x": -7,
            "y": 1,
            "z": 0,
            "elements": [
                "nuclearcraft:electromagnet_supercooler_active@0"
            ]
        },
        {
            "x": -6,
            "y": 1,
            "z": 0,
            "elements": [
                "nuclearcraft:electromagnet_supercooler_active@0"
            ]
        },
        {
            "x": -5,
            "y": 1,
            "z": 0,
            "elements": [
                "nuclearcraft:electromagnet_supercooler_active@0"
            ]
        },
        {
            "x": -20,
            "y": 1,
            "z": 16,
            "elements": [
                "nuclearcraft:electromagnet_supercooler_active@0"
            ]
        },
        {
            "x": -4,
            "y": 1,
            "z": 0,
            "elements": [
                "nuclearcraft:electromagnet_supercooler_active@0"
            ]
        },
        {
            "x": -20,
            "y": -1,
            "z": 15,
            "elements": [
                "nuclearcraft:electromagnet_supercooler_active@0"
            ]
        },
        {
            "x": -3,
            "y": 1,
            "z": 0,
            "elements": [
                "nuclearcraft:electromagnet_supercooler_active@0"
            ]
        },
        {
            "x": -19,
            "y": 1,
            "z": 16,
            "elements": [
                "nuclearcraft:accelerator_electromagnet_active@0"
            ]
        },
        {
            "x": -2,
            "y": 1,
            "z": 0,
            "elements": [
                "nuclearcraft:electromagnet_supercooler_active@0"
            ]
        },
        {
            "x": -19,
            "y": -1,
            "z": 15,
            "elements": [
                "nuclearcraft:accelerator_electromagnet_active@0"
            ]
        },
        {
            "x": -18,
            "y": 1,
            "z": 16,
            "elements": [
                "nuclearcraft:electromagnet_supercooler_active@0"
            ]
        },
        {
            "x": 0,
            "y": -1,
            "z": 0,
            "elements": [
                "nuclearcraft:electromagnet_supercooler_active@0"
            ]
        },
        {
            "x": -1,
            "y": 1,
            "z": 0,
            "elements": [
                "nuclearcraft:electromagnet_supercooler_active@0"
            ]
        },
        {
            "x": -18,
            "y": -1,
            "z": 15,
            "elements": [
                "nuclearcraft:electromagnet_supercooler_active@0"
            ]
        },
        {
            "x": 0,
            "y": 1,
            "z": 0,
            "elements": [
                "nuclearcraft:electromagnet_supercooler_active@0"
            ]
        },
        {
            "x": -1,
            "y": -1,
            "z": 0,
            "elements": [
                "nuclearcraft:electromagnet_supercooler_active@0"
            ]
        },
        {
            "x": -2,
            "y": -1,
            "z": 0,
            "elements": [
                "nuclearcraft:electromagnet_supercooler_active@0"
            ]
        },
        {
            "x": -3,
            "y": -1,
            "z": 0,
            "elements": [
                "nuclearcraft:electromagnet_supercooler_active@0"
            ]
        },
        {
            "x": -4,
            "y": -1,
            "z": 0,
            "elements": [
                "nuclearcraft:electromagnet_supercooler_active@0"
            ]
        },
        {
            "x": -5,
            "y": -1,
            "z": 0,
            "elements": [
                "nuclearcraft:electromagnet_supercooler_active@0"
            ]
        },
        {
            "x": -6,
            "y": -1,
            "z": 0,
            "elements": [
                "nuclearcraft:electromagnet_supercooler_active@0"
            ]
        },
        {
            "x": -7,
            "y": -1,
            "z": 0,
            "elements": [
                "nuclearcraft:electromagnet_supercooler_active@0"
            ]
        },
        {
            "x": -8,
            "y": -1,
            "z": 0,
            "elements": [
                "nuclearcraft:electromagnet_supercooler_active@0"
            ]
        },
        {
            "x": -9,
            "y": -1,
            "z": 0,
            "elements": [
                "nuclearcraft:electromagnet_supercooler_active@0"
            ]
        },
        {
            "x": -10,
            "y": -1,
            "z": 0,
            "elements": [
                "nuclearcraft:electromagnet_supercooler_active@0"
            ]
        },
        {
            "x": -11,
            "y": -1,
            "z": 0,
            "elements": [
                "nuclearcraft:electromagnet_supercooler_active@0"
            ]
        },
        {
            "x": -12,
            "y": -1,
            "z": 0,
            "elements": [
                "nuclearcraft:electromagnet_supercooler_active@0"
            ]
        },
        {
            "x": -13,
            "y": -1,
            "z": 0,
            "elements": [
                "nuclearcraft:electromagnet_supercooler_active@0"
            ]
        },
        {
            "x": -14,
            "y": -1,
            "z": 0,
            "elements": [
                "nuclearcraft:electromagnet_supercooler_active@0"
            ]
        },
        {
            "x": -15,
            "y": -1,
            "z": 0,
            "elements": [
                "nuclearcraft:electromagnet_supercooler_active@0"
            ]
        },
        {
            "x": -2,
            "y": 1,
            "z": 16,
            "elements": [
                "nuclearcraft:electromagnet_supercooler_active@0"
            ]
        },
        {
            "x": -16,
            "y": -1,
            "z": 0,
            "elements": [
                "nuclearcraft:electromagnet_supercooler_active@0"
            ]
        },
        {
            "x": -2,
            "y": -1,
            "z": 15,
            "elements": [
                "nuclearcraft:electromagnet_supercooler_active@0"
            ]
        },
        {
            "x": -1,
            "y": 1,
            "z": 16,
            "elements": [
                "nuclearcraft:accelerator_electromagnet_active@0"
            ]
        },
        {
            "x": 0,
            "y": 1,
            "z": 16,
            "elements": [
                "nuclearcraft:electromagnet_supercooler_active@0"
            ]
        },
        {
            "x": -17,
            "y": -1,
            "z": 0,
            "elements": [
                "nuclearcraft:electromagnet_supercooler_active@0"
            ]
        },
        {
            "x": -1,
            "y": -1,
            "z": 15,
            "elements": [
                "nuclearcraft:accelerator_electromagnet_active@0"
            ]
        },
        {
            "x": 0,
            "y": -1,
            "z": 15,
            "elements": [
                "nuclearcraft:electromagnet_supercooler_active@0"
            ]
        },
        {
            "x": -18,
            "y": -1,
            "z": 0,
            "elements": [
                "nuclearcraft:electromagnet_supercooler_active@0"
            ]
        },
        {
            "x": -19,
            "y": -1,
            "z": 0,
            "elements": [
                "nuclearcraft:electromagnet_supercooler_active@0"
            ]
        },
        {
            "x": -20,
            "y": -1,
            "z": 0,
            "elements": [
                "nuclearcraft:electromagnet_supercooler_active@0"
            ]
        },
        {
            "x": -20,
            "y": 0,
            "z": 15,
            "elements": [
                "nuclearcraft:accelerator_electromagnet_active@0"
            ]
        },
        {
            "x": -18,
            "y": 0,
            "z": 15,
            "elements": [
                "nuclearcraft:accelerator_electromagnet_active@0"
            ]
        },
        {
            "x": -2,
            "y": 0,
            "z": 15,
            "elements": [
                "nuclearcraft:accelerator_electromagnet_active@0"
            ]
        },
        {
            "x": 0,
            "y": 0,
            "z": 15,
            "elements": [
                "nuclearcraft:accelerator_electromagnet_active@0"
            ]
        },
        {
            "x": -20,
            "y": 1,
            "z": 15,
            "elements": [
                "nuclearcraft:electromagnet_supercooler_active@0"
            ]
        },
        {
            "x": -20,
            "y": -1,
            "z": 14,
            "elements": [
                "nuclearcraft:electromagnet_supercooler_active@0"
            ]
        },
        {
            "x": -19,
            "y": 1,
            "z": 15,
            "elements": [
                "nuclearcraft:accelerator_electromagnet_active@0"
            ]
        },
        {
            "x": -19,
            "y": -1,
            "z": 14,
            "elements": [
                "nuclearcraft:accelerator_electromagnet_active@0"
            ]
        },
        {
            "x": -18,
            "y": 1,
            "z": 15,
            "elements": [
                "nuclearcraft:electromagnet_supercooler_active@0"
            ]
        },
        {
            "x": -18,
            "y": -1,
            "z": 14,
            "elements": [
                "nuclearcraft:electromagnet_supercooler_active@0"
            ]
        },
        {
            "x": -2,
            "y": 1,
            "z": 15,
            "elements": [
                "nuclearcraft:electromagnet_supercooler_active@0"
            ]
        },
        {
            "x": -2,
            "y": -1,
            "z": 14,
            "elements": [
                "nuclearcraft:electromagnet_supercooler_active@0"
            ]
        },
        {
            "x": -1,
            "y": 1,
            "z": 15,
            "elements": [
                "nuclearcraft:accelerator_electromagnet_active@0"
            ]
        },
        {
            "x": 0,
            "y": 1,
            "z": 15,
            "elements": [
                "nuclearcraft:electromagnet_supercooler_active@0"
            ]
        },
        {
            "x": -1,
            "y": -1,
            "z": 14,
            "elements": [
                "nuclearcraft:accelerator_electromagnet_active@0"
            ]
        },
        {
            "x": 0,
            "y": -1,
            "z": 14,
            "elements": [
                "nuclearcraft:electromagnet_supercooler_active@0"
            ]
        },
        {
            "x": -20,
            "y": 0,
            "z": 14,
            "elements": [
                "nuclearcraft:accelerator_electromagnet_active@0"
            ]
        },
        {
            "x": -18,
            "y": 0,
            "z": 14,
            "elements": [
                "nuclearcraft:accelerator_electromagnet_active@0"
            ]
        },
        {
            "x": -2,
            "y": 0,
            "z": 14,
            "elements": [
                "nuclearcraft:accelerator_electromagnet_active@0"
            ]
        },
        {
            "x": 0,
            "y": 0,
            "z": 14,
            "elements": [
                "nuclearcraft:accelerator_electromagnet_active@0"
            ]
        },
        {
            "x": -20,
            "y": 1,
            "z": 14,
            "elements": [
                "nuclearcraft:electromagnet_supercooler_active@0"
            ]
        },
        {
            "x": -20,
            "y": -1,
            "z": 13,
            "elements": [
                "nuclearcraft:electromagnet_supercooler_active@0"
            ]
        },
        {
            "x": -19,
            "y": 1,
            "z": 14,
            "elements": [
                "nuclearcraft:accelerator_electromagnet_active@0"
            ]
        },
        {
            "x": -19,
            "y": -1,
            "z": 13,
            "elements": [
                "nuclearcraft:accelerator_electromagnet_active@0"
            ]
        },
        {
            "x": -18,
            "y": 1,
            "z": 14,
            "elements": [
                "nuclearcraft:electromagnet_supercooler_active@0"
            ]
        },
        {
            "x": -18,
            "y": -1,
            "z": 13,
            "elements": [
                "nuclearcraft:electromagnet_supercooler_active@0"
            ]
        },
        {
            "x": -2,
            "y": 1,
            "z": 14,
            "elements": [
                "nuclearcraft:electromagnet_supercooler_active@0"
            ]
        },
        {
            "x": -2,
            "y": -1,
            "z": 13,
            "elements": [
                "nuclearcraft:electromagnet_supercooler_active@0"
            ]
        },
        {
            "x": -1,
            "y": 1,
            "z": 14,
            "elements": [
                "nuclearcraft:accelerator_electromagnet_active@0"
            ]
        },
        {
            "x": 0,
            "y": 1,
            "z": 14,
            "elements": [
                "nuclearcraft:electromagnet_supercooler_active@0"
            ]
        },
        {
            "x": -1,
            "y": -1,
            "z": 13,
            "elements": [
                "nuclearcraft:accelerator_electromagnet_active@0"
            ]
        },
        {
            "x": 0,
            "y": -1,
            "z": 13,
            "elements": [
                "nuclearcraft:electromagnet_supercooler_active@0"
            ]
        },
        {
            "x": -20,
            "y": 0,
            "z": 13,
            "elements": [
                "nuclearcraft:accelerator_electromagnet_active@0"
            ]
        },
        {
            "x": -18,
            "y": 0,
            "z": 13,
            "elements": [
                "nuclearcraft:accelerator_electromagnet_active@0"
            ]
        },
        {
            "x": -2,
            "y": 0,
            "z": 13,
            "elements": [
                "nuclearcraft:accelerator_electromagnet_active@0"
            ]
        },
        {
            "x": 0,
            "y": 0,
            "z": 13,
            "elements": [
                "nuclearcraft:accelerator_electromagnet_active@0"
            ]
        },
        {
            "x": -20,
            "y": 1,
            "z": 13,
            "elements": [
                "nuclearcraft:electromagnet_supercooler_active@0"
            ]
        },
        {
            "x": -20,
            "y": -1,
            "z": 12,
            "elements": [
                "nuclearcraft:electromagnet_supercooler_active@0"
            ]
        },
        {
            "x": -19,
            "y": 1,
            "z": 13,
            "elements": [
                "nuclearcraft:accelerator_electromagnet_active@0"
            ]
        },
        {
            "x": -19,
            "y": -1,
            "z": 12,
            "elements": [
                "nuclearcraft:accelerator_electromagnet_active@0"
            ]
        },
        {
            "x": -18,
            "y": 1,
            "z": 13,
            "elements": [
                "nuclearcraft:electromagnet_supercooler_active@0"
            ]
        },
        {
            "x": -18,
            "y": -1,
            "z": 12,
            "elements": [
                "nuclearcraft:electromagnet_supercooler_active@0"
            ]
        },
        {
            "x": -2,
            "y": 1,
            "z": 13,
            "elements": [
                "nuclearcraft:electromagnet_supercooler_active@0"
            ]
        },
        {
            "x": -2,
            "y": -1,
            "z": 12,
            "elements": [
                "nuclearcraft:electromagnet_supercooler_active@0"
            ]
        },
        {
            "x": -1,
            "y": 1,
            "z": 13,
            "elements": [
                "nuclearcraft:accelerator_electromagnet_active@0"
            ]
        },
        {
            "x": 0,
            "y": 1,
            "z": 13,
            "elements": [
                "nuclearcraft:electromagnet_supercooler_active@0"
            ]
        },
        {
            "x": -1,
            "y": -1,
            "z": 12,
            "elements": [
                "nuclearcraft:accelerator_electromagnet_active@0"
            ]
        },
        {
            "x": 0,
            "y": -1,
            "z": 12,
            "elements": [
                "nuclearcraft:electromagnet_supercooler_active@0"
            ]
        },
        {
            "x": -20,
            "y": 0,
            "z": 12,
            "elements": [
                "nuclearcraft:accelerator_electromagnet_active@0"
            ]
        },
        {
            "x": -18,
            "y": 0,
            "z": 12,
            "elements": [
                "nuclearcraft:accelerator_electromagnet_active@0"
            ]
        },
        {
            "x": -2,
            "y": 0,
            "z": 12,
            "elements": [
                "nuclearcraft:accelerator_electromagnet_active@0"
            ]
        },
        {
            "x": 0,
            "y": 0,
            "z": 12,
            "elements": [
                "nuclearcraft:accelerator_electromagnet_active@0"
            ]
        },
        {
            "x": -20,
            "y": 1,
            "z": 12,
            "elements": [
                "nuclearcraft:electromagnet_supercooler_active@0"
            ]
        },
        {
            "x": -20,
            "y": -1,
            "z": 11,
            "elements": [
                "nuclearcraft:electromagnet_supercooler_active@0"
            ]
        },
        {
            "x": -19,
            "y": 1,
            "z": 12,
            "elements": [
                "nuclearcraft:accelerator_electromagnet_active@0"
            ]
        },
        {
            "x": -19,
            "y": -1,
            "z": 11,
            "elements": [
                "nuclearcraft:accelerator_electromagnet_active@0"
            ]
        },
        {
            "x": -18,
            "y": 1,
            "z": 12,
            "elements": [
                "nuclearcraft:electromagnet_supercooler_active@0"
            ]
        },
        {
            "x": -18,
            "y": -1,
            "z": 11,
            "elements": [
                "nuclearcraft:electromagnet_supercooler_active@0"
            ]
        },
        {
            "x": -2,
            "y": 1,
            "z": 12,
            "elements": [
                "nuclearcraft:electromagnet_supercooler_active@0"
            ]
        },
        {
            "x": -2,
            "y": -1,
            "z": 11,
            "elements": [
                "nuclearcraft:electromagnet_supercooler_active@0"
            ]
        },
        {
            "x": -1,
            "y": 1,
            "z": 12,
            "elements": [
                "nuclearcraft:accelerator_electromagnet_active@0"
            ]
        },
        {
            "x": 0,
            "y": 1,
            "z": 12,
            "elements": [
                "nuclearcraft:electromagnet_supercooler_active@0"
            ]
        },
        {
            "x": -1,
            "y": -1,
            "z": 11,
            "elements": [
                "nuclearcraft:accelerator_electromagnet_active@0"
            ]
        },
        {
            "x": 0,
            "y": -1,
            "z": 11,
            "elements": [
                "nuclearcraft:electromagnet_supercooler_active@0"
            ]
        },
        {
            "x": -20,
            "y": 0,
            "z": 11,
            "elements": [
                "nuclearcraft:accelerator_electromagnet_active@0"
            ]
        },
        {
            "x": -18,
            "y": 0,
            "z": 11,
            "elements": [
                "nuclearcraft:accelerator_electromagnet_active@0"
            ]
        },
        {
            "x": -2,
            "y": 0,
            "z": 11,
            "elements": [
                "nuclearcraft:accelerator_electromagnet_active@0"
            ]
        },
        {
            "x": 0,
            "y": 0,
            "z": 11,
            "elements": [
                "nuclearcraft:accelerator_electromagnet_active@0"
            ]
        },
        {
            "x": -20,
            "y": 1,
            "z": 11,
            "elements": [
                "nuclearcraft:electromagnet_supercooler_active@0"
            ]
        },
        {
            "x": -20,
            "y": -1,
            "z": 10,
            "elements": [
                "nuclearcraft:electromagnet_supercooler_active@0"
            ]
        },
        {
            "x": -19,
            "y": 1,
            "z": 11,
            "elements": [
                "nuclearcraft:accelerator_electromagnet_active@0"
            ]
        },
        {
            "x": -19,
            "y": -1,
            "z": 10,
            "elements": [
                "nuclearcraft:accelerator_electromagnet_active@0"
            ]
        },
        {
            "x": -18,
            "y": 1,
            "z": 11,
            "elements": [
                "nuclearcraft:electromagnet_supercooler_active@0"
            ]
        },
        {
            "x": -18,
            "y": -1,
            "z": 10,
            "elements": [
                "nuclearcraft:electromagnet_supercooler_active@0"
            ]
        },
        {
            "x": -2,
            "y": 1,
            "z": 11,
            "elements": [
                "nuclearcraft:electromagnet_supercooler_active@0"
            ]
        },
        {
            "x": -2,
            "y": -1,
            "z": 10,
            "elements": [
                "nuclearcraft:electromagnet_supercooler_active@0"
            ]
        },
        {
            "x": -1,
            "y": 1,
            "z": 11,
            "elements": [
                "nuclearcraft:accelerator_electromagnet_active@0"
            ]
        },
        {
            "x": 0,
            "y": 1,
            "z": 11,
            "elements": [
                "nuclearcraft:electromagnet_supercooler_active@0"
            ]
        },
        {
            "x": -1,
            "y": -1,
            "z": 10,
            "elements": [
                "nuclearcraft:accelerator_electromagnet_active@0"
            ]
        },
        {
            "x": 0,
            "y": -1,
            "z": 10,
            "elements": [
                "nuclearcraft:electromagnet_supercooler_active@0"
            ]
        },
        {
            "x": -20,
            "y": 0,
            "z": 10,
            "elements": [
                "nuclearcraft:accelerator_electromagnet_active@0"
            ]
        },
        {
            "x": -18,
            "y": 0,
            "z": 10,
            "elements": [
                "nuclearcraft:accelerator_electromagnet_active@0"
            ]
        },
        {
            "x": -2,
            "y": 0,
            "z": 10,
            "elements": [
                "nuclearcraft:accelerator_electromagnet_active@0"
            ]
        },
        {
            "x": 0,
            "y": 0,
            "z": 10,
            "elements": [
                "nuclearcraft:accelerator_electromagnet_active@0"
            ]
        },
        {
            "x": -20,
            "y": 1,
            "z": 10,
            "elements": [
                "nuclearcraft:electromagnet_supercooler_active@0"
            ]
        },
        {
            "x": -20,
            "y": -1,
            "z": 9,
            "elements": [
                "nuclearcraft:electromagnet_supercooler_active@0"
            ]
        },
        {
            "x": -19,
            "y": 1,
            "z": 10,
            "elements": [
                "nuclearcraft:accelerator_electromagnet_active@0"
            ]
        },
        {
            "x": -19,
            "y": -1,
            "z": 9,
            "elements": [
                "nuclearcraft:accelerator_electromagnet_active@0"
            ]
        },
        {
            "x": -18,
            "y": 1,
            "z": 10,
            "elements": [
                "nuclearcraft:electromagnet_supercooler_active@0"
            ]
        },
        {
            "x": -18,
            "y": -1,
            "z": 9,
            "elements": [
                "nuclearcraft:electromagnet_supercooler_active@0"
            ]
        },
        {
            "x": -2,
            "y": 1,
            "z": 10,
            "elements": [
                "nuclearcraft:electromagnet_supercooler_active@0"
            ]
        },
        {
            "x": -2,
            "y": -1,
            "z": 9,
            "elements": [
                "nuclearcraft:electromagnet_supercooler_active@0"
            ]
        },
        {
            "x": -1,
            "y": 1,
            "z": 10,
            "elements": [
                "nuclearcraft:accelerator_electromagnet_active@0"
            ]
        },
        {
            "x": 0,
            "y": 1,
            "z": 10,
            "elements": [
                "nuclearcraft:electromagnet_supercooler_active@0"
            ]
        },
        {
            "x": -1,
            "y": -1,
            "z": 9,
            "elements": [
                "nuclearcraft:accelerator_electromagnet_active@0"
            ]
        },
        {
            "x": 0,
            "y": -1,
            "z": 9,
            "elements": [
                "nuclearcraft:electromagnet_supercooler_active@0"
            ]
        },
        {
            "x": -20,
            "y": 0,
            "z": 9,
            "elements": [
                "nuclearcraft:accelerator_electromagnet_active@0"
            ]
        },
        {
            "x": -18,
            "y": 0,
            "z": 9,
            "elements": [
                "nuclearcraft:accelerator_electromagnet_active@0"
            ]
        },
        {
            "x": -2,
            "y": 0,
            "z": 9,
            "elements": [
                "nuclearcraft:accelerator_electromagnet_active@0"
            ]
        },
        {
            "x": 0,
            "y": 0,
            "z": 9,
            "elements": [
                "nuclearcraft:accelerator_electromagnet_active@0"
            ]
        },
        {
            "x": -20,
            "y": 1,
            "z": 9,
            "elements": [
                "nuclearcraft:electromagnet_supercooler_active@0"
            ]
        },
        {
            "x": -20,
            "y": -1,
            "z": 8,
            "elements": [
                "nuclearcraft:electromagnet_supercooler_active@0"
            ]
        },
        {
            "x": -19,
            "y": 1,
            "z": 9,
            "elements": [
                "nuclearcraft:accelerator_electromagnet_active@0"
            ]
        },
        {
            "x": -19,
            "y": -1,
            "z": 8,
            "elements": [
                "nuclearcraft:accelerator_electromagnet_active@0"
            ]
        },
        {
            "x": -18,
            "y": 1,
            "z": 9,
            "elements": [
                "nuclearcraft:electromagnet_supercooler_active@0"
            ]
        },
        {
            "x": -18,
            "y": -1,
            "z": 8,
            "elements": [
                "nuclearcraft:electromagnet_supercooler_active@0"
            ]
        },
        {
            "x": -2,
            "y": 1,
            "z": 9,
            "elements": [
                "nuclearcraft:electromagnet_supercooler_active@0"
            ]
        },
        {
            "x": -2,
            "y": -1,
            "z": 8,
            "elements": [
                "nuclearcraft:electromagnet_supercooler_active@0"
            ]
        },
        {
            "x": -1,
            "y": 1,
            "z": 9,
            "elements": [
                "nuclearcraft:accelerator_electromagnet_active@0"
            ]
        },
        {
            "x": 0,
            "y": 1,
            "z": 9,
            "elements": [
                "nuclearcraft:electromagnet_supercooler_active@0"
            ]
        },
        {
            "x": -1,
            "y": -1,
            "z": 8,
            "elements": [
                "nuclearcraft:accelerator_electromagnet_active@0"
            ]
        },
        {
            "x": 0,
            "y": -1,
            "z": 8,
            "elements": [
                "nuclearcraft:electromagnet_supercooler_active@0"
            ]
        },
        {
            "x": -20,
            "y": 0,
            "z": 8,
            "elements": [
                "nuclearcraft:accelerator_electromagnet_active@0"
            ]
        },
        {
            "x": -18,
            "y": 0,
            "z": 8,
            "elements": [
                "nuclearcraft:accelerator_electromagnet_active@0"
            ]
        },
        {
            "x": -2,
            "y": 0,
            "z": 8,
            "elements": [
                "nuclearcraft:accelerator_electromagnet_active@0"
            ]
        },
        {
            "x": 0,
            "y": 0,
            "z": 8,
            "elements": [
                "nuclearcraft:accelerator_electromagnet_active@0"
            ]
        },
        {
            "x": -20,
            "y": 1,
            "z": 8,
            "elements": [
                "nuclearcraft:electromagnet_supercooler_active@0"
            ]
        },
        {
            "x": -20,
            "y": -1,
            "z": 7,
            "elements": [
                "nuclearcraft:electromagnet_supercooler_active@0"
            ]
        },
        {
            "x": -19,
            "y": 1,
            "z": 8,
            "elements": [
                "nuclearcraft:accelerator_electromagnet_active@0"
            ]
        },
        {
            "x": -19,
            "y": -1,
            "z": 7,
            "elements": [
                "nuclearcraft:accelerator_electromagnet_active@0"
            ]
        },
        {
            "x": -18,
            "y": 1,
            "z": 8,
            "elements": [
                "nuclearcraft:electromagnet_supercooler_active@0"
            ]
        },
        {
            "x": -18,
            "y": -1,
            "z": 7,
            "elements": [
                "nuclearcraft:electromagnet_supercooler_active@0"
            ]
        },
        {
            "x": -2,
            "y": 1,
            "z": 8,
            "elements": [
                "nuclearcraft:electromagnet_supercooler_active@0"
            ]
        },
        {
            "x": -2,
            "y": -1,
            "z": 7,
            "elements": [
                "nuclearcraft:electromagnet_supercooler_active@0"
            ]
        },
        {
            "x": -1,
            "y": 1,
            "z": 8,
            "elements": [
                "nuclearcraft:accelerator_electromagnet_active@0"
            ]
        },
        {
            "x": 0,
            "y": 1,
            "z": 8,
            "elements": [
                "nuclearcraft:electromagnet_supercooler_active@0"
            ]
        },
        {
            "x": -1,
            "y": -1,
            "z": 7,
            "elements": [
                "nuclearcraft:accelerator_electromagnet_active@0"
            ]
        },
        {
            "x": 0,
            "y": -1,
            "z": 7,
            "elements": [
                "nuclearcraft:electromagnet_supercooler_active@0"
            ]
        },
        {
            "x": -20,
            "y": 0,
            "z": 7,
            "elements": [
                "nuclearcraft:accelerator_electromagnet_active@0"
            ]
        },
        {
            "x": -18,
            "y": 0,
            "z": 7,
            "elements": [
                "nuclearcraft:accelerator_electromagnet_active@0"
            ]
        },
        {
            "x": -2,
            "y": 0,
            "z": 7,
            "elements": [
                "nuclearcraft:accelerator_electromagnet_active@0"
            ]
        },
        {
            "x": 0,
            "y": 0,
            "z": 7,
            "elements": [
                "nuclearcraft:accelerator_electromagnet_active@0"
            ]
        },
        {
            "x": -20,
            "y": 1,
            "z": 7,
            "elements": [
                "nuclearcraft:electromagnet_supercooler_active@0"
            ]
        },
        {
            "x": -20,
            "y": -1,
            "z": 6,
            "elements": [
                "nuclearcraft:electromagnet_supercooler_active@0"
            ]
        },
        {
            "x": -19,
            "y": 1,
            "z": 7,
            "elements": [
                "nuclearcraft:accelerator_electromagnet_active@0"
            ]
        },
        {
            "x": -19,
            "y": -1,
            "z": 6,
            "elements": [
                "nuclearcraft:accelerator_electromagnet_active@0"
            ]
        },
        {
            "x": -18,
            "y": 1,
            "z": 7,
            "elements": [
                "nuclearcraft:electromagnet_supercooler_active@0"
            ]
        },
        {
            "x": -18,
            "y": -1,
            "z": 6,
            "elements": [
                "nuclearcraft:electromagnet_supercooler_active@0"
            ]
        },
        {
            "x": -2,
            "y": 1,
            "z": 7,
            "elements": [
                "nuclearcraft:electromagnet_supercooler_active@0"
            ]
        },
        {
            "x": -2,
            "y": -1,
            "z": 6,
            "elements": [
                "nuclearcraft:electromagnet_supercooler_active@0"
            ]
        },
        {
            "x": -1,
            "y": 1,
            "z": 7,
            "elements": [
                "nuclearcraft:accelerator_electromagnet_active@0"
            ]
        },
        {
            "x": 0,
            "y": 1,
            "z": 7,
            "elements": [
                "nuclearcraft:electromagnet_supercooler_active@0"
            ]
        },
        {
            "x": -1,
            "y": -1,
            "z": 6,
            "elements": [
                "nuclearcraft:accelerator_electromagnet_active@0"
            ]
        },
        {
            "x": 0,
            "y": -1,
            "z": 6,
            "elements": [
                "nuclearcraft:electromagnet_supercooler_active@0"
            ]
        },
        {
            "x": -20,
            "y": 0,
            "z": 6,
            "elements": [
                "nuclearcraft:accelerator_electromagnet_active@0"
            ]
        },
        {
            "x": -18,
            "y": 0,
            "z": 6,
            "elements": [
                "nuclearcraft:accelerator_electromagnet_active@0"
            ]
        },
        {
            "x": -2,
            "y": 0,
            "z": 6,
            "elements": [
                "nuclearcraft:accelerator_electromagnet_active@0"
            ]
        },
        {
            "x": 0,
            "y": 0,
            "z": 6,
            "elements": [
                "nuclearcraft:accelerator_electromagnet_active@0"
            ]
        },
        {
            "x": -20,
            "y": 1,
            "z": 6,
            "elements": [
                "nuclearcraft:electromagnet_supercooler_active@0"
            ]
        },
        {
            "x": -20,
            "y": -1,
            "z": 5,
            "elements": [
                "nuclearcraft:electromagnet_supercooler_active@0"
            ]
        },
        {
            "x": -19,
            "y": 1,
            "z": 6,
            "elements": [
                "nuclearcraft:accelerator_electromagnet_active@0"
            ]
        },
        {
            "x": -19,
            "y": -1,
            "z": 5,
            "elements": [
                "nuclearcraft:accelerator_electromagnet_active@0"
            ]
        },
        {
            "x": -18,
            "y": 1,
            "z": 6,
            "elements": [
                "nuclearcraft:electromagnet_supercooler_active@0"
            ]
        },
        {
            "x": -18,
            "y": -1,
            "z": 5,
            "elements": [
                "nuclearcraft:electromagnet_supercooler_active@0"
            ]
        },
        {
            "x": -2,
            "y": 1,
            "z": 6,
            "elements": [
                "nuclearcraft:electromagnet_supercooler_active@0"
            ]
        },
        {
            "x": -2,
            "y": -1,
            "z": 5,
            "elements": [
                "nuclearcraft:electromagnet_supercooler_active@0"
            ]
        },
        {
            "x": -1,
            "y": 1,
            "z": 6,
            "elements": [
                "nuclearcraft:accelerator_electromagnet_active@0"
            ]
        },
        {
            "x": 0,
            "y": 1,
            "z": 6,
            "elements": [
                "nuclearcraft:electromagnet_supercooler_active@0"
            ]
        },
        {
            "x": -1,
            "y": -1,
            "z": 5,
            "elements": [
                "nuclearcraft:accelerator_electromagnet_active@0"
            ]
        },
        {
            "x": 0,
            "y": -1,
            "z": 5,
            "elements": [
                "nuclearcraft:electromagnet_supercooler_active@0"
            ]
        },
        {
            "x": -20,
            "y": 0,
            "z": 5,
            "elements": [
                "nuclearcraft:accelerator_electromagnet_active@0"
            ]
        },
        {
            "x": -18,
            "y": 0,
            "z": 5,
            "elements": [
                "nuclearcraft:accelerator_electromagnet_active@0"
            ]
        },
        {
            "x": -2,
            "y": 0,
            "z": 5,
            "elements": [
                "nuclearcraft:accelerator_electromagnet_active@0"
            ]
        },
        {
            "x": 0,
            "y": 0,
            "z": 5,
            "elements": [
                "nuclearcraft:accelerator_electromagnet_active@0"
            ]
        },
        {
            "x": -20,
            "y": 1,
            "z": 5,
            "elements": [
                "nuclearcraft:electromagnet_supercooler_active@0"
            ]
        },
        {
            "x": -20,
            "y": -1,
            "z": 4,
            "elements": [
                "nuclearcraft:electromagnet_supercooler_active@0"
            ]
        },
        {
            "x": -19,
            "y": 1,
            "z": 5,
            "elements": [
                "nuclearcraft:accelerator_electromagnet_active@0"
            ]
        },
        {
            "x": -19,
            "y": -1,
            "z": 4,
            "elements": [
                "nuclearcraft:accelerator_electromagnet_active@0"
            ]
        },
        {
            "x": -18,
            "y": 1,
            "z": 5,
            "elements": [
                "nuclearcraft:electromagnet_supercooler_active@0"
            ]
        },
        {
            "x": -18,
            "y": -1,
            "z": 4,
            "elements": [
                "nuclearcraft:electromagnet_supercooler_active@0"
            ]
        },
        {
            "x": -20,
            "y": -1,
            "z": 20,
            "elements": [
                "nuclearcraft:electromagnet_supercooler_active@0"
            ]
        },
        {
            "x": -19,
            "y": -1,
            "z": 20,
            "elements": [
                "nuclearcraft:electromagnet_supercooler_active@0"
            ]
        },
        {
            "x": -2,
            "y": 1,
            "z": 5,
            "elements": [
                "nuclearcraft:electromagnet_supercooler_active@0"
            ]
        },
        {
            "x": -18,
            "y": -1,
            "z": 20,
            "elements": [
                "nuclearcraft:electromagnet_supercooler_active@0"
            ]
        },
        {
            "x": -2,
            "y": -1,
            "z": 4,
            "elements": [
                "nuclearcraft:electromagnet_supercooler_active@0"
            ]
        },
        {
            "x": -1,
            "y": 1,
            "z": 5,
            "elements": [
                "nuclearcraft:accelerator_electromagnet_active@0"
            ]
        },
        {
            "x": 0,
            "y": 1,
            "z": 5,
            "elements": [
                "nuclearcraft:electromagnet_supercooler_active@0"
            ]
        },
        {
            "x": -17,
            "y": -1,
            "z": 20,
            "elements": [
                "nuclearcraft:electromagnet_supercooler_active@0"
            ]
        },
        {
            "x": -1,
            "y": -1,
            "z": 4,
            "elements": [
                "nuclearcraft:accelerator_electromagnet_active@0"
            ]
        },
        {
            "x": 0,
            "y": -1,
            "z": 4,
            "elements": [
                "nuclearcraft:electromagnet_supercooler_active@0"
            ]
        },
        {
            "x": -16,
            "y": -1,
            "z": 20,
            "elements": [
                "nuclearcraft:electromagnet_supercooler_active@0"
            ]
        },
        {
            "x": -15,
            "y": -1,
            "z": 20,
            "elements": [
                "nuclearcraft:electromagnet_supercooler_active@0"
            ]
        },
        {
            "x": -14,
            "y": -1,
            "z": 20,
            "elements": [
                "nuclearcraft:electromagnet_supercooler_active@0"
            ]
        },
        {
            "x": -13,
            "y": -1,
            "z": 20,
            "elements": [
                "nuclearcraft:electromagnet_supercooler_active@0"
            ]
        },
        {
            "x": -12,
            "y": -1,
            "z": 20,
            "elements": [
                "nuclearcraft:electromagnet_supercooler_active@0"
            ]
        },
        {
            "x": -11,
            "y": -1,
            "z": 20,
            "elements": [
                "nuclearcraft:electromagnet_supercooler_active@0"
            ]
        },
        {
            "x": -10,
            "y": -1,
            "z": 20,
            "elements": [
                "nuclearcraft:electromagnet_supercooler_active@0"
            ]
        },
        {
            "x": -9,
            "y": -1,
            "z": 20,
            "elements": [
                "nuclearcraft:electromagnet_supercooler_active@0"
            ]
        },
        {
            "x": -8,
            "y": -1,
            "z": 20,
            "elements": [
                "nuclearcraft:electromagnet_supercooler_active@0"
            ]
        },
        {
            "x": -7,
            "y": -1,
            "z": 20,
            "elements": [
                "nuclearcraft:electromagnet_supercooler_active@0"
            ]
        },
        {
            "x": -6,
            "y": -1,
            "z": 20,
            "elements": [
                "nuclearcraft:electromagnet_supercooler_active@0"
            ]
        },
        {
            "x": -5,
            "y": -1,
            "z": 20,
            "elements": [
                "nuclearcraft:electromagnet_supercooler_active@0"
            ]
        },
        {
            "x": -20,
            "y": 0,
            "z": 4,
            "elements": [
                "nuclearcraft:accelerator_electromagnet_active@0"
            ]
        },
        {
            "x": -4,
            "y": -1,
            "z": 20,
            "elements": [
                "nuclearcraft:electromagnet_supercooler_active@0"
            ]
        },
        {
            "x": -3,
            "y": -1,
            "z": 20,
            "elements": [
                "nuclearcraft:electromagnet_supercooler_active@0"
            ]
        },
        {
            "x": -18,
            "y": 0,
            "z": 4,
            "elements": [
                "nuclearcraft:accelerator_electromagnet_active@0"
            ]
        },
        {
            "x": -2,
            "y": -1,
            "z": 20,
            "elements": [
                "nuclearcraft:electromagnet_supercooler_active@0"
            ]
        },
        {
            "x": -1,
            "y": -1,
            "z": 20,
            "elements": [
                "nuclearcraft:electromagnet_supercooler_active@0"
            ]
        },
        {
            "x": 0,
            "y": -1,
            "z": 20,
            "elements": [
                "nuclearcraft:electromagnet_supercooler_active@0"
            ]
        },
        {
            "x": -20,
            "y": 0,
            "z": 20,
            "elements": [
                "nuclearcraft:accelerator_electromagnet_active@0"
            ]
        },
        {
            "x": -19,
            "y": 0,
            "z": 20,
            "elements": [
                "nuclearcraft:accelerator_electromagnet_active@0"
            ]
        },
        {
            "x": -18,
            "y": 0,
            "z": 20,
            "elements": [
                "nuclearcraft:accelerator_electromagnet_active@0"
            ]
        },
        {
            "x": -2,
            "y": 0,
            "z": 4,
            "elements": [
                "nuclearcraft:accelerator_electromagnet_active@0"
            ]
        },
        {
            "x": -17,
            "y": 0,
            "z": 20,
            "elements": [
                "nuclearcraft:accelerator_electromagnet_active@0"
            ]
        },
        {
            "x": 0,
            "y": 0,
            "z": 4,
            "elements": [
                "nuclearcraft:accelerator_electromagnet_active@0"
            ]
        },
        {
            "x": -16,
            "y": 0,
            "z": 20,
            "elements": [
                "nuclearcraft:accelerator_electromagnet_active@0"
            ]
        },
        {
            "x": -15,
            "y": 0,
            "z": 20,
            "elements": [
                "nuclearcraft:accelerator_electromagnet_active@0"
            ]
        },
        {
            "x": -14,
            "y": 0,
            "z": 20,
            "elements": [
                "nuclearcraft:accelerator_electromagnet_active@0"
            ]
        },
        {
            "x": -13,
            "y": 0,
            "z": 20,
            "elements": [
                "nuclearcraft:accelerator_electromagnet_active@0"
            ]
        },
        {
            "x": -12,
            "y": 0,
            "z": 20,
            "elements": [
                "nuclearcraft:accelerator_electromagnet_active@0"
            ]
        },
        {
            "x": -11,
            "y": 0,
            "z": 20,
            "elements": [
                "nuclearcraft:accelerator_electromagnet_active@0"
            ]
        },
        {
            "x": -10,
            "y": 0,
            "z": 20,
            "elements": [
                "nuclearcraft:accelerator_electromagnet_active@0"
            ]
        },
        {
            "x": -9,
            "y": 0,
            "z": 20,
            "elements": [
                "nuclearcraft:accelerator_electromagnet_active@0"
            ]
        },
        {
            "x": -8,
            "y": 0,
            "z": 20,
            "elements": [
                "nuclearcraft:accelerator_electromagnet_active@0"
            ]
        },
        {
            "x": -7,
            "y": 0,
            "z": 20,
            "elements": [
                "nuclearcraft:accelerator_electromagnet_active@0"
            ]
        },
        {
            "x": -6,
            "y": 0,
            "z": 20,
            "elements": [
                "nuclearcraft:accelerator_electromagnet_active@0"
            ]
        },
        {
            "x": -5,
            "y": 0,
            "z": 20,
            "elements": [
                "nuclearcraft:accelerator_electromagnet_active@0"
            ]
        },
        {
            "x": -20,
            "y": 1,
            "z": 4,
            "elements": [
                "nuclearcraft:electromagnet_supercooler_active@0"
            ]
        },
        {
            "x": -4,
            "y": 0,
            "z": 20,
            "elements": [
                "nuclearcraft:accelerator_electromagnet_active@0"
            ]
        },
        {
            "x": -20,
            "y": -1,
            "z": 3,
            "elements": [
                "nuclearcraft:electromagnet_supercooler_active@0"
            ]
        },
        {
            "x": -19,
            "y": 1,
            "z": 4,
            "elements": [
                "nuclearcraft:accelerator_electromagnet_active@0"
            ]
        },
        {
            "x": -3,
            "y": 0,
            "z": 20,
            "elements": [
                "nuclearcraft:accelerator_electromagnet_active@0"
            ]
        },
        {
            "x": -19,
            "y": -1,
            "z": 3,
            "elements": [
                "nuclearcraft:accelerator_electromagnet_active@0"
            ]
        },
        {
            "x": -18,
            "y": 1,
            "z": 4,
            "elements": [
                "nuclearcraft:electromagnet_supercooler_active@0"
            ]
        },
        {
            "x": -2,
            "y": 0,
            "z": 20,
            "elements": [
                "nuclearcraft:accelerator_electromagnet_active@0"
            ]
        },
        {
            "x": -18,
            "y": -1,
            "z": 3,
            "elements": [
                "nuclearcraft:electromagnet_supercooler_active@0"
            ]
        },
        {
            "x": -1,
            "y": 0,
            "z": 20,
            "elements": [
                "nuclearcraft:accelerator_electromagnet_active@0"
            ]
        },
        {
            "x": 0,
            "y": 0,
            "z": 20,
            "elements": [
                "nuclearcraft:accelerator_electromagnet_active@0"
            ]
        },
        {
            "x": -20,
            "y": 1,
            "z": 20,
            "elements": [
                "nuclearcraft:electromagnet_supercooler_active@0"
            ]
        },
        {
            "x": -19,
            "y": 1,
            "z": 20,
            "elements": [
                "nuclearcraft:electromagnet_supercooler_active@0"
            ]
        },
        {
            "x": -20,
            "y": -1,
            "z": 19,
            "elements": [
                "nuclearcraft:electromagnet_supercooler_active@0"
            ]
        },
        {
            "x": -18,
            "y": 1,
            "z": 20,
            "elements": [
                "nuclearcraft:electromagnet_supercooler_active@0"
            ]
        },
        {
            "x": -19,
            "y": -1,
            "z": 19,
            "elements": [
                "nuclearcraft:accelerator_electromagnet_active@0"
            ]
        },
        {
            "x": -2,
            "y": 1,
            "z": 4,
            "elements": [
                "nuclearcraft:electromagnet_supercooler_active@0"
            ]
        },
        {
            "x": -17,
            "y": 1,
            "z": 20,
            "elements": [
                "nuclearcraft:electromagnet_supercooler_active@0"
            ]
        },
        {
            "x": -18,
            "y": -1,
            "z": 19,
            "elements": [
                "nuclearcraft:accelerator_electromagnet_active@0"
            ]
        },
        {
            "x": -2,
            "y": -1,
            "z": 3,
            "elements": [
                "nuclearcraft:electromagnet_supercooler_active@0"
            ]
        },
        {
            "x": -1,
            "y": 1,
            "z": 4,
            "elements": [
                "nuclearcraft:accelerator_electromagnet_active@0"
            ]
        },
        {
            "x": 0,
            "y": 1,
            "z": 4,
            "elements": [
                "nuclearcraft:electromagnet_supercooler_active@0"
            ]
        },
        {
            "x": -16,
            "y": 1,
            "z": 20,
            "elements": [
                "nuclearcraft:electromagnet_supercooler_active@0"
            ]
        },
        {
            "x": -17,
            "y": -1,
            "z": 19,
            "elements": [
                "nuclearcraft:accelerator_electromagnet_active@0"
            ]
        },
        {
            "x": -1,
            "y": -1,
            "z": 3,
            "elements": [
                "nuclearcraft:accelerator_electromagnet_active@0"
            ]
        },
        {
            "x": 0,
            "y": -1,
            "z": 3,
            "elements": [
                "nuclearcraft:electromagnet_supercooler_active@0"
            ]
        },
        {
            "x": -15,
            "y": 1,
            "z": 20,
            "elements": [
                "nuclearcraft:electromagnet_supercooler_active@0"
            ]
        },
        {
            "x": -16,
            "y": -1,
            "z": 19,
            "elements": [
                "nuclearcraft:accelerator_electromagnet_active@0"
            ]
        },
        {
            "x": -14,
            "y": 1,
            "z": 20,
            "elements": [
                "nuclearcraft:electromagnet_supercooler_active@0"
            ]
        },
        {
            "x": -15,
            "y": -1,
            "z": 19,
            "elements": [
                "nuclearcraft:accelerator_electromagnet_active@0"
            ]
        },
        {
            "x": -13,
            "y": 1,
            "z": 20,
            "elements": [
                "nuclearcraft:electromagnet_supercooler_active@0"
            ]
        },
        {
            "x": -14,
            "y": -1,
            "z": 19,
            "elements": [
                "nuclearcraft:accelerator_electromagnet_active@0"
            ]
        },
        {
            "x": -12,
            "y": 1,
            "z": 20,
            "elements": [
                "nuclearcraft:electromagnet_supercooler_active@0"
            ]
        },
        {
            "x": -13,
            "y": -1,
            "z": 19,
            "elements": [
                "nuclearcraft:accelerator_electromagnet_active@0"
            ]
        },
        {
            "x": -11,
            "y": 1,
            "z": 20,
            "elements": [
                "nuclearcraft:electromagnet_supercooler_active@0"
            ]
        },
        {
            "x": -12,
            "y": -1,
            "z": 19,
            "elements": [
                "nuclearcraft:accelerator_electromagnet_active@0"
            ]
        },
        {
            "x": -10,
            "y": 1,
            "z": 20,
            "elements": [
                "nuclearcraft:electromagnet_supercooler_active@0"
            ]
        },
        {
            "x": -11,
            "y": -1,
            "z": 19,
            "elements": [
                "nuclearcraft:accelerator_electromagnet_active@0"
            ]
        },
        {
            "x": -9,
            "y": 1,
            "z": 20,
            "elements": [
                "nuclearcraft:electromagnet_supercooler_active@0"
            ]
        },
        {
            "x": -10,
            "y": -1,
            "z": 19,
            "elements": [
                "nuclearcraft:accelerator_electromagnet_active@0"
            ]
        },
        {
            "x": -8,
            "y": 1,
            "z": 20,
            "elements": [
                "nuclearcraft:electromagnet_supercooler_active@0"
            ]
        },
        {
            "x": -9,
            "y": -1,
            "z": 19,
            "elements": [
                "nuclearcraft:accelerator_electromagnet_active@0"
            ]
        },
        {
            "x": -7,
            "y": 1,
            "z": 20,
            "elements": [
                "nuclearcraft:electromagnet_supercooler_active@0"
            ]
        },
        {
            "x": -8,
            "y": -1,
            "z": 19,
            "elements": [
                "nuclearcraft:accelerator_electromagnet_active@0"
            ]
        },
        {
            "x": -6,
            "y": 1,
            "z": 20,
            "elements": [
                "nuclearcraft:electromagnet_supercooler_active@0"
            ]
        },
        {
            "x": -7,
            "y": -1,
            "z": 19,
            "elements": [
                "nuclearcraft:accelerator_electromagnet_active@0"
            ]
        },
        {
            "x": -5,
            "y": 1,
            "z": 20,
            "elements": [
                "nuclearcraft:electromagnet_supercooler_active@0"
            ]
        },
        {
            "x": -6,
            "y": -1,
            "z": 19,
            "elements": [
                "nuclearcraft:accelerator_electromagnet_active@0"
            ]
        },
        {
            "x": -4,
            "y": 1,
            "z": 20,
            "elements": [
                "nuclearcraft:electromagnet_supercooler_active@0"
            ]
        },
        {
            "x": -20,
            "y": 0,
            "z": 3,
            "elements": [
                "nuclearcraft:accelerator_electromagnet_active@0"
            ]
        },
        {
            "x": -5,
            "y": -1,
            "z": 19,
            "elements": [
                "nuclearcraft:accelerator_electromagnet_active@0"
            ]
        },
        {
            "x": -3,
            "y": 1,
            "z": 20,
            "elements": [
                "nuclearcraft:electromagnet_supercooler_active@0"
            ]
        },
        {
            "x": -4,
            "y": -1,
            "z": 19,
            "elements": [
                "nuclearcraft:accelerator_electromagnet_active@0"
            ]
        },
        {
            "x": -2,
            "y": 1,
            "z": 20,
            "elements": [
                "nuclearcraft:electromagnet_supercooler_active@0"
            ]
        },
        {
            "x": -3,
            "y": -1,
            "z": 19,
            "elements": [
                "nuclearcraft:accelerator_electromagnet_active@0"
            ]
        },
        {
            "x": -18,
            "y": 0,
            "z": 3,
            "elements": [
                "nuclearcraft:accelerator_electromagnet_active@0"
            ]
        },
        {
            "x": -1,
            "y": 1,
            "z": 20,
            "elements": [
                "nuclearcraft:electromagnet_supercooler_active@0"
            ]
        },
        {
            "x": -2,
            "y": -1,
            "z": 19,
            "elements": [
                "nuclearcraft:accelerator_electromagnet_active@0"
            ]
        },
        {
            "x": 0,
            "y": 1,
            "z": 20,
            "elements": [
                "nuclearcraft:electromagnet_supercooler_active@0"
            ]
        },
        {
            "x": -1,
            "y": -1,
            "z": 19,
            "elements": [
                "nuclearcraft:accelerator_electromagnet_active@0"
            ]
        },
        {
            "x": 0,
            "y": -1,
            "z": 19,
            "elements": [
                "nuclearcraft:electromagnet_supercooler_active@0"
            ]
        },
        {
            "x": -20,
            "y": 0,
            "z": 19,
            "elements": [
                "nuclearcraft:accelerator_electromagnet_active@0"
            ]
        },
        {
            "x": -2,
            "y": 0,
            "z": 3,
            "elements": [
                "nuclearcraft:accelerator_electromagnet_active@0"
            ]
        },
        {
            "x": 0,
            "y": 0,
            "z": 3,
            "elements": [
                "nuclearcraft:accelerator_electromagnet_active@0"
            ]
        },
        {
            "x": -20,
            "y": 1,
            "z": 3,
            "elements": [
                "nuclearcraft:electromagnet_supercooler_active@0"
            ]
        },
        {
            "x": -20,
            "y": -1,
            "z": 2,
            "elements": [
                "nuclearcraft:electromagnet_supercooler_active@0"
            ]
        },
        {
            "x": -19,
            "y": 1,
            "z": 3,
            "elements": [
                "nuclearcraft:accelerator_electromagnet_active@0"
            ]
        },
        {
            "x": -19,
            "y": -1,
            "z": 2,
            "elements": [
                "nuclearcraft:accelerator_electromagnet_active@0"
            ]
        },
        {
            "x": -18,
            "y": 1,
            "z": 3,
            "elements": [
                "nuclearcraft:electromagnet_supercooler_active@0"
            ]
        },
        {
            "x": -18,
            "y": -1,
            "z": 2,
            "elements": [
                "nuclearcraft:electromagnet_supercooler_active@0"
            ]
        },
        {
            "x": -17,
            "y": -1,
            "z": 2,
            "elements": [
                "nuclearcraft:electromagnet_supercooler_active@0"
            ]
        },
        {
            "x": 0,
            "y": 0,
            "z": 19,
            "elements": [
                "nuclearcraft:accelerator_electromagnet_active@0"
            ]
        },
        {
            "x": -16,
            "y": -1,
            "z": 2,
            "elements": [
                "nuclearcraft:electromagnet_supercooler_active@0"
            ]
        },
        {
            "x": -15,
            "y": -1,
            "z": 2,
            "elements": [
                "nuclearcraft:electromagnet_supercooler_active@0"
            ]
        },
        {
            "x": -14,
            "y": -1,
            "z": 2,
            "elements": [
                "nuclearcraft:electromagnet_supercooler_active@0"
            ]
        },
        {
            "x": -13,
            "y": -1,
            "z": 2,
            "elements": [
                "nuclearcraft:electromagnet_supercooler_active@0"
            ]
        },
        {
            "x": -12,
            "y": -1,
            "z": 2,
            "elements": [
                "nuclearcraft:electromagnet_supercooler_active@0"
            ]
        },
        {
            "x": -11,
            "y": -1,
            "z": 2,
            "elements": [
                "nuclearcraft:electromagnet_supercooler_active@0"
            ]
        },
        {
            "x": -10,
            "y": -1,
            "z": 2,
            "elements": [
                "nuclearcraft:electromagnet_supercooler_active@0"
            ]
        },
        {
            "x": -9,
            "y": -1,
            "z": 2,
            "elements": [
                "nuclearcraft:electromagnet_supercooler_active@0"
            ]
        },
        {
            "x": -8,
            "y": -1,
            "z": 2,
            "elements": [
                "nuclearcraft:electromagnet_supercooler_active@0"
            ]
        },
        {
            "x": -7,
            "y": -1,
            "z": 2,
            "elements": [
                "nuclearcraft:electromagnet_supercooler_active@0"
            ]
        },
        {
            "x": -6,
            "y": -1,
            "z": 2,
            "elements": [
                "nuclearcraft:electromagnet_supercooler_active@0"
            ]
        },
        {
            "x": -20,
            "y": 1,
            "z": 19,
            "elements": [
                "nuclearcraft:electromagnet_supercooler_active@0"
            ]
        },
        {
            "x": -5,
            "y": -1,
            "z": 2,
            "elements": [
                "nuclearcraft:electromagnet_supercooler_active@0"
            ]
        },
        {
            "x": -20,
            "y": -1,
            "z": 18,
            "elements": [
                "nuclearcraft:electromagnet_supercooler_active@0"
            ]
        },
        {
            "x": -4,
            "y": -1,
            "z": 2,
            "elements": [
                "nuclearcraft:electromagnet_supercooler_active@0"
            ]
        },
        {
            "x": -19,
            "y": 1,
            "z": 19,
            "elements": [
                "nuclearcraft:accelerator_electromagnet_active@0"
            ]
        },
        {
            "x": -3,
            "y": -1,
            "z": 2,
            "elements": [
                "nuclearcraft:electromagnet_supercooler_active@0"
            ]
        },
        {
            "x": -19,
            "y": -1,
            "z": 18,
            "elements": [
                "nuclearcraft:accelerator_electromagnet_active@0"
            ]
        },
        {
            "x": -2,
            "y": 1,
            "z": 3,
            "elements": [
                "nuclearcraft:electromagnet_supercooler_active@0"
            ]
        },
        {
            "x": -18,
            "y": 1,
            "z": 19,
            "elements": [
                "nuclearcraft:accelerator_electromagnet_active@0"
            ]
        },
        {
            "x": -1,
            "y": 1,
            "z": 3,
            "elements": [
                "nuclearcraft:accelerator_electromagnet_active@0"
            ]
        },
        {
            "x": -17,
            "y": 1,
            "z": 19,
            "elements": [
                "nuclearcraft:accelerator_electromagnet_active@0"
            ]
        },
        {
            "x": -18,
            "y": -1,
            "z": 18,
            "elements": [
                "nuclearcraft:electromagnet_supercooler_active@0"
            ]
        },
        {
            "x": -2,
            "y": -1,
            "z": 2,
            "elements": [
                "nuclearcraft:electromagnet_supercooler_active@0"
            ]
        },
        {
            "x": 0,
            "y": 1,
            "z": 3,
            "elements": [
                "nuclearcraft:electromagnet_supercooler_active@0"
            ]
        },
        {
            "x": -1,
            "y": -1,
            "z": 2,
            "elements": [
                "nuclearcraft:accelerator_electromagnet_active@0"
            ]
        },
        {
            "x": -17,
            "y": -1,
            "z": 18,
            "elements": [
                "nuclearcraft:electromagnet_supercooler_active@0"
            ]
        },
        {
            "x": -16,
            "y": 1,
            "z": 19,
            "elements": [
                "nuclearcraft:accelerator_electromagnet_active@0"
            ]
        },
        {
            "x": 0,
            "y": -1,
            "z": 2,
            "elements": [
                "nuclearcraft:electromagnet_supercooler_active@0"
            ]
        },
        {
            "x": -16,
            "y": -1,
            "z": 18,
            "elements": [
                "nuclearcraft:electromagnet_supercooler_active@0"
            ]
        },
        {
            "x": -15,
            "y": 1,
            "z": 19,
            "elements": [
                "nuclearcraft:accelerator_electromagnet_active@0"
            ]
        },
        {
            "x": -15,
            "y": -1,
            "z": 18,
            "elements": [
                "nuclearcraft:electromagnet_supercooler_active@0"
            ]
        },
        {
            "x": -14,
            "y": 1,
            "z": 19,
            "elements": [
                "nuclearcraft:accelerator_electromagnet_active@0"
            ]
        },
        {
            "x": -14,
            "y": -1,
            "z": 18,
            "elements": [
                "nuclearcraft:electromagnet_supercooler_active@0"
            ]
        },
        {
            "x": -13,
            "y": 1,
            "z": 19,
            "elements": [
                "nuclearcraft:accelerator_electromagnet_active@0"
            ]
        },
        {
            "x": -13,
            "y": -1,
            "z": 18,
            "elements": [
                "nuclearcraft:electromagnet_supercooler_active@0"
            ]
        },
        {
            "x": -12,
            "y": 1,
            "z": 19,
            "elements": [
                "nuclearcraft:accelerator_electromagnet_active@0"
            ]
        },
        {
            "x": -12,
            "y": -1,
            "z": 18,
            "elements": [
                "nuclearcraft:electromagnet_supercooler_active@0"
            ]
        },
        {
            "x": -11,
            "y": 1,
            "z": 19,
            "elements": [
                "nuclearcraft:accelerator_electromagnet_active@0"
            ]
        },
        {
            "x": -11,
            "y": -1,
            "z": 18,
            "elements": [
                "nuclearcraft:electromagnet_supercooler_active@0"
            ]
        },
        {
            "x": -10,
            "y": 1,
            "z": 19,
            "elements": [
                "nuclearcraft:accelerator_electromagnet_active@0"
            ]
        },
        {
            "x": -10,
            "y": -1,
            "z": 18,
            "elements": [
                "nuclearcraft:electromagnet_supercooler_active@0"
            ]
        },
        {
            "x": -9,
            "y": 1,
            "z": 19,
            "elements": [
                "nuclearcraft:accelerator_electromagnet_active@0"
            ]
        },
        {
            "x": -9,
            "y": -1,
            "z": 18,
            "elements": [
                "nuclearcraft:electromagnet_supercooler_active@0"
            ]
        },
        {
            "x": -8,
            "y": 1,
            "z": 19,
            "elements": [
                "nuclearcraft:accelerator_electromagnet_active@0"
            ]
        },
        {
            "x": -8,
            "y": -1,
            "z": 18,
            "elements": [
                "nuclearcraft:electromagnet_supercooler_active@0"
            ]
        },
        {
            "x": -7,
            "y": 1,
            "z": 19,
            "elements": [
                "nuclearcraft:accelerator_electromagnet_active@0"
            ]
        },
        {
            "x": -7,
            "y": -1,
            "z": 18,
            "elements": [
                "nuclearcraft:electromagnet_supercooler_active@0"
            ]
        },
        {
            "x": -6,
            "y": 1,
            "z": 19,
            "elements": [
                "nuclearcraft:accelerator_electromagnet_active@0"
            ]
        },
        {
            "x": -6,
            "y": -1,
            "z": 18,
            "elements": [
                "nuclearcraft:electromagnet_supercooler_active@0"
            ]
        },
        {
            "x": -5,
            "y": 1,
            "z": 19,
            "elements": [
                "nuclearcraft:accelerator_electromagnet_active@0"
            ]
        },
        {
            "x": -20,
            "y": 0,
            "z": 2,
            "elements": [
                "nuclearcraft:accelerator_electromagnet_active@0"
            ]
        },
        {
            "x": -5,
            "y": -1,
            "z": 18,
            "elements": [
                "nuclearcraft:electromagnet_supercooler_active@0"
            ]
        },
        {
            "x": -4,
            "y": 1,
            "z": 19,
            "elements": [
                "nuclearcraft:accelerator_electromagnet_active@0"
            ]
        },
        {
            "x": -4,
            "y": -1,
            "z": 18,
            "elements": [
                "nuclearcraft:electromagnet_supercooler_active@0"
            ]
        },
        {
            "x": -3,
            "y": 1,
            "z": 19,
            "elements": [
                "nuclearcraft:accelerator_electromagnet_active@0"
            ]
        },
        {
            "x": -3,
            "y": -1,
            "z": 18,
            "elements": [
                "nuclearcraft:electromagnet_supercooler_active@0"
            ]
        },
        {
            "x": -2,
            "y": 1,
            "z": 19,
            "elements": [
                "nuclearcraft:accelerator_electromagnet_active@0"
            ]
        },
        {
            "x": -18,
            "y": 0,
            "z": 2,
            "elements": [
                "nuclearcraft:accelerator_electromagnet_active@0"
            ]
        },
        {
            "x": -1,
            "y": 1,
            "z": 19,
            "elements": [
                "nuclearcraft:accelerator_electromagnet_active@0"
            ]
        },
        {
            "x": -17,
            "y": 0,
            "z": 2,
            "elements": [
                "nuclearcraft:accelerator_electromagnet_active@0"
            ]
        },
        {
            "x": -2,
            "y": -1,
            "z": 18,
            "elements": [
                "nuclearcraft:electromagnet_supercooler_active@0"
            ]
        },
        {
            "x": 0,
            "y": 1,
            "z": 19,
            "elements": [
                "nuclearcraft:electromagnet_supercooler_active@0"
            ]
        },
        {
            "x": -1,
            "y": -1,
            "z": 18,
            "elements": [
                "nuclearcraft:accelerator_electromagnet_active@0"
            ]
        },
        {
            "x": -16,
            "y": 0,
            "z": 2,
            "elements": [
                "nuclearcraft:accelerator_electromagnet_active@0"
            ]
        },
        {
            "x": 0,
            "y": -1,
            "z": 18,
            "elements": [
                "nuclearcraft:electromagnet_supercooler_active@0"
            ]
        },
        {
            "x": -15,
            "y": 0,
            "z": 2,
            "elements": [
                "nuclearcraft:accelerator_electromagnet_active@0"
            ]
        },
        {
            "x": -14,
            "y": 0,
            "z": 2,
            "elements": [
                "nuclearcraft:accelerator_electromagnet_active@0"
            ]
        },
        {
            "x": -13,
            "y": 0,
            "z": 2,
            "elements": [
                "nuclearcraft:accelerator_electromagnet_active@0"
            ]
        },
        {
            "x": -12,
            "y": 0,
            "z": 2,
            "elements": [
                "nuclearcraft:accelerator_electromagnet_active@0"
            ]
        },
        {
            "x": -11,
            "y": 0,
            "z": 2,
            "elements": [
                "nuclearcraft:accelerator_electromagnet_active@0"
            ]
        },
        {
            "x": -10,
            "y": 0,
            "z": 2,
            "elements": [
                "nuclearcraft:accelerator_electromagnet_active@0"
            ]
        },
        {
            "x": -9,
            "y": 0,
            "z": 2,
            "elements": [
                "nuclearcraft:accelerator_electromagnet_active@0"
            ]
        },
        {
            "x": -8,
            "y": 0,
            "z": 2,
            "elements": [
                "nuclearcraft:accelerator_electromagnet_active@0"
            ]
        },
        {
            "x": -7,
            "y": 0,
            "z": 2,
            "elements": [
                "nuclearcraft:accelerator_electromagnet_active@0"
            ]
        },
        {
            "x": -6,
            "y": 0,
            "z": 2,
            "elements": [
                "nuclearcraft:accelerator_electromagnet_active@0"
            ]
        },
        {
            "x": -5,
            "y": 0,
            "z": 2,
            "elements": [
                "nuclearcraft:accelerator_electromagnet_active@0"
            ]
        },
        {
            "x": -20,
            "y": 0,
            "z": 18,
            "elements": [
                "nuclearcraft:accelerator_electromagnet_active@0"
            ]
        },
        {
            "x": -4,
            "y": 0,
            "z": 2,
            "elements": [
                "nuclearcraft:accelerator_electromagnet_active@0"
            ]
        },
        {
            "x": -3,
            "y": 0,
            "z": 2,
            "elements": [
                "nuclearcraft:accelerator_electromagnet_active@0"
            ]
        },
        {
            "x": -18,
            "y": 0,
            "z": 18,
            "elements": [
                "nuclearcraft:accelerator_electromagnet_active@0"
            ]
        },
        {
            "x": -2,
            "y": 0,
            "z": 2,
            "elements": [
                "nuclearcraft:accelerator_electromagnet_active@0"
            ]
        },
        {
            "x": -17,
            "y": 0,
            "z": 18,
            "elements": [
                "nuclearcraft:accelerator_electromagnet_active@0"
            ]
        },
        {
            "x": 0,
            "y": 0,
            "z": 2,
            "elements": [
                "nuclearcraft:accelerator_electromagnet_active@0"
            ]
        },
        {
            "x": -16,
            "y": 0,
            "z": 18,
            "elements": [
                "nuclearcraft:accelerator_electromagnet_active@0"
            ]
        },
        {
            "x": -15,
            "y": 0,
            "z": 18,
            "elements": [
                "nuclearcraft:accelerator_electromagnet_active@0"
            ]
        },
        {
            "x": -14,
            "y": 0,
            "z": 18,
            "elements": [
                "nuclearcraft:accelerator_electromagnet_active@0"
            ]
        },
        {
            "x": -13,
            "y": 0,
            "z": 18,
            "elements": [
                "nuclearcraft:accelerator_electromagnet_active@0"
            ]
        },
        {
            "x": -12,
            "y": 0,
            "z": 18,
            "elements": [
                "nuclearcraft:accelerator_electromagnet_active@0"
            ]
        },
        {
            "x": -11,
            "y": 0,
            "z": 18,
            "elements": [
                "nuclearcraft:accelerator_electromagnet_active@0"
            ]
        },
        {
            "x": -10,
            "y": 0,
            "z": 18,
            "elements": [
                "nuclearcraft:accelerator_electromagnet_active@0"
            ]
        },
        {
            "x": -9,
            "y": 0,
            "z": 18,
            "elements": [
                "nuclearcraft:accelerator_electromagnet_active@0"
            ]
        },
        {
            "x": -8,
            "y": 0,
            "z": 18,
            "elements": [
                "nuclearcraft:accelerator_electromagnet_active@0"
            ]
        },
        {
            "x": -7,
            "y": 0,
            "z": 18,
            "elements": [
                "nuclearcraft:accelerator_electromagnet_active@0"
            ]
        },
        {
            "x": -6,
            "y": 0,
            "z": 18,
            "elements": [
                "nuclearcraft:accelerator_electromagnet_active@0"
            ]
        },
        {
            "x": -20,
            "y": 1,
            "z": 2,
            "elements": [
                "nuclearcraft:electromagnet_supercooler_active@0"
            ]
        },
        {
            "x": -5,
            "y": 0,
            "z": 18,
            "elements": [
                "nuclearcraft:accelerator_electromagnet_active@0"
            ]
        },
        {
            "x": -20,
            "y": -1,
            "z": 1,
            "elements": [
                "nuclearcraft:electromagnet_supercooler_active@0"
            ]
        },
        {
            "x": -19,
            "y": 1,
            "z": 2,
            "elements": [
                "nuclearcraft:accelerator_electromagnet_active@0"
            ]
        },
        {
            "x": -4,
            "y": 0,
            "z": 18,
            "elements": [
                "nuclearcraft:accelerator_electromagnet_active@0"
            ]
        },
        {
            "x": -19,
            "y": -1,
            "z": 1,
            "elements": [
                "nuclearcraft:accelerator_electromagnet_active@0"
            ]
        },
        {
            "x": -18,
            "y": 1,
            "z": 2,
            "elements": [
                "nuclearcraft:electromagnet_supercooler_active@0"
            ]
        },
        {
            "x": -3,
            "y": 0,
            "z": 18,
            "elements": [
                "nuclearcraft:accelerator_electromagnet_active@0"
            ]
        },
        {
            "x": -18,
            "y": -1,
            "z": 1,
            "elements": [
                "nuclearcraft:accelerator_electromagnet_active@0"
            ]
        },
        {
            "x": -17,
            "y": 1,
            "z": 2,
            "elements": [
                "nuclearcraft:electromagnet_supercooler_active@0"
            ]
        },
        {
            "x": -2,
            "y": 0,
            "z": 18,
            "elements": [
                "nuclearcraft:accelerator_electromagnet_active@0"
            ]
        },
        {
            "x": -17,
            "y": -1,
            "z": 1,
            "elements": [
                "nuclearcraft:accelerator_electromagnet_active@0"
            ]
        },
        {
            "x": -16,
            "y": 1,
            "z": 2,
            "elements": [
                "nuclearcraft:electromagnet_supercooler_active@0"
            ]
        },
        {
            "x": 0,
            "y": 0,
            "z": 18,
            "elements": [
                "nuclearcraft:accelerator_electromagnet_active@0"
            ]
        },
        {
            "x": -16,
            "y": -1,
            "z": 1,
            "elements": [
                "nuclearcraft:accelerator_electromagnet_active@0"
            ]
        },
        {
            "x": -15,
            "y": 1,
            "z": 2,
            "elements": [
                "nuclearcraft:electromagnet_supercooler_active@0"
            ]
        },
        {
            "x": -15,
            "y": -1,
            "z": 1,
            "elements": [
                "nuclearcraft:accelerator_electromagnet_active@0"
            ]
        },
        {
            "x": -14,
            "y": 1,
            "z": 2,
            "elements": [
                "nuclearcraft:electromagnet_supercooler_active@0"
            ]
        },
        {
            "x": -14,
            "y": -1,
            "z": 1,
            "elements": [
                "nuclearcraft:accelerator_electromagnet_active@0"
            ]
        },
        {
            "x": -13,
            "y": 1,
            "z": 2,
            "elements": [
                "nuclearcraft:electromagnet_supercooler_active@0"
            ]
        },
        {
            "x": -13,
            "y": -1,
            "z": 1,
            "elements": [
                "nuclearcraft:accelerator_electromagnet_active@0"
            ]
        },
        {
            "x": -12,
            "y": 1,
            "z": 2,
            "elements": [
                "nuclearcraft:electromagnet_supercooler_active@0"
            ]
        },
        {
            "x": -12,
            "y": -1,
            "z": 1,
            "elements": [
                "nuclearcraft:accelerator_electromagnet_active@0"
            ]
        },
        {
            "x": -11,
            "y": 1,
            "z": 2,
            "elements": [
                "nuclearcraft:electromagnet_supercooler_active@0"
            ]
        },
        {
            "x": -11,
            "y": -1,
            "z": 1,
            "elements": [
                "nuclearcraft:accelerator_electromagnet_active@0"
            ]
        },
        {
            "x": -10,
            "y": 1,
            "z": 2,
            "elements": [
                "nuclearcraft:electromagnet_supercooler_active@0"
            ]
        },
        {
            "x": -10,
            "y": -1,
            "z": 1,
            "elements": [
                "nuclearcraft:accelerator_electromagnet_active@0"
            ]
        },
        {
            "x": -9,
            "y": 1,
            "z": 2,
            "elements": [
                "nuclearcraft:electromagnet_supercooler_active@0"
            ]
        },
        {
            "x": -9,
            "y": -1,
            "z": 1,
            "elements": [
                "nuclearcraft:accelerator_electromagnet_active@0"
            ]
        },
        {
            "x": -8,
            "y": 1,
            "z": 2,
            "elements": [
                "nuclearcraft:electromagnet_supercooler_active@0"
            ]
        },
        {
            "x": -8,
            "y": -1,
            "z": 1,
            "elements": [
                "nuclearcraft:accelerator_electromagnet_active@0"
            ]
        },
        {
            "x": -7,
            "y": 1,
            "z": 2,
            "elements": [
                "nuclearcraft:electromagnet_supercooler_active@0"
            ]
        },
        {
            "x": -7,
            "y": -1,
            "z": 1,
            "elements": [
                "nuclearcraft:accelerator_electromagnet_active@0"
            ]
        },
        {
            "x": -6,
            "y": 1,
            "z": 2,
            "elements": [
                "nuclearcraft:electromagnet_supercooler_active@0"
            ]
        },
        {
            "x": -6,
            "y": -1,
            "z": 1,
            "elements": [
                "nuclearcraft:accelerator_electromagnet_active@0"
            ]
        },
        {
            "x": -5,
            "y": 1,
            "z": 2,
            "elements": [
                "nuclearcraft:electromagnet_supercooler_active@0"
            ]
        },
        {
            "x": -20,
            "y": 1,
            "z": 18,
            "elements": [
                "nuclearcraft:electromagnet_supercooler_active@0"
            ]
        },
        {
            "x": -5,
            "y": -1,
            "z": 1,
            "elements": [
                "nuclearcraft:accelerator_electromagnet_active@0"
            ]
        },
        {
            "x": -4,
            "y": 1,
            "z": 2,
            "elements": [
                "nuclearcraft:electromagnet_supercooler_active@0"
            ]
        },
        {
            "x": -20,
            "y": -1,
            "z": 17,
            "elements": [
                "nuclearcraft:electromagnet_supercooler_active@0"
            ]
        },
        {
            "x": -4,
            "y": -1,
            "z": 1,
            "elements": [
                "nuclearcraft:accelerator_electromagnet_active@0"
            ]
        },
        {
            "x": -19,
            "y": 1,
            "z": 18,
            "elements": [
                "nuclearcraft:accelerator_electromagnet_active@0"
            ]
        },
        {
            "x": -3,
            "y": 1,
            "z": 2,
            "elements": [
                "nuclearcraft:electromagnet_supercooler_active@0"
            ]
        },
        {
            "x": -3,
            "y": -1,
            "z": 1,
            "elements": [
                "nuclearcraft:accelerator_electromagnet_active@0"
            ]
        },
        {
            "x": -19,
            "y": -1,
            "z": 17,
            "elements": [
                "nuclearcraft:accelerator_electromagnet_active@0"
            ]
        },
        {
            "x": -2,
            "y": 1,
            "z": 2,
            "elements": [
                "nuclearcraft:electromagnet_supercooler_active@0"
            ]
        },
        {
            "x": -18,
            "y": 1,
            "z": 18,
            "elements": [
                "nuclearcraft:electromagnet_supercooler_active@0"
            ]
        },
        {
            "x": -2,
            "y": -1,
            "z": 1,
            "elements": [
                "nuclearcraft:accelerator_electromagnet_active@0"
            ]
        },
        {
            "x": -18,
            "y": -1,
            "z": 17,
            "elements": [
                "nuclearcraft:electromagnet_supercooler_active@0"
            ]
        },
        {
            "x": -1,
            "y": 1,
            "z": 2,
            "elements": [
                "nuclearcraft:accelerator_electromagnet_active@0"
            ]
        },
        {
            "x": -17,
            "y": 1,
            "z": 18,
            "elements": [
                "nuclearcraft:electromagnet_supercooler_active@0"
            ]
        },
        {
            "x": 0,
            "y": 1,
            "z": 2,
            "elements": [
                "nuclearcraft:electromagnet_supercooler_active@0"
            ]
        },
        {
            "x": -1,
            "y": -1,
            "z": 1,
            "elements": [
                "nuclearcraft:accelerator_electromagnet_active@0"
            ]
        },
        {
            "x": -16,
            "y": 1,
            "z": 18,
            "elements": [
                "nuclearcraft:electromagnet_supercooler_active@0"
            ]
        },
        {
            "x": 0,
            "y": -1,
            "z": 1,
            "elements": [
                "nuclearcraft:electromagnet_supercooler_active@0"
            ]
        },
        {
            "x": -15,
            "y": 1,
            "z": 18,
            "elements": [
                "nuclearcraft:electromagnet_supercooler_active@0"
            ]
        },
        {
            "x": -14,
            "y": 1,
            "z": 18,
            "elements": [
                "nuclearcraft:electromagnet_supercooler_active@0"
            ]
        },
        {
            "x": -13,
            "y": 1,
            "z": 18,
            "elements": [
                "nuclearcraft:electromagnet_supercooler_active@0"
            ]
        },
        {
            "x": -12,
            "y": 1,
            "z": 18,
            "elements": [
                "nuclearcraft:electromagnet_supercooler_active@0"
            ]
        },
        {
            "x": -11,
            "y": 1,
            "z": 18,
            "elements": [
                "nuclearcraft:electromagnet_supercooler_active@0"
            ]
        },
        {
            "x": -10,
            "y": 1,
            "z": 18,
            "elements": [
                "nuclearcraft:electromagnet_supercooler_active@0"
            ]
        },
        {
            "x": -9,
            "y": 1,
            "z": 18,
            "elements": [
                "nuclearcraft:electromagnet_supercooler_active@0"
            ]
        },
        {
            "x": -8,
            "y": 1,
            "z": 18,
            "elements": [
                "nuclearcraft:electromagnet_supercooler_active@0"
            ]
        },
        {
            "x": -7,
            "y": 1,
            "z": 18,
            "elements": [
                "nuclearcraft:electromagnet_supercooler_active@0"
            ]
        },
        {
            "x": -6,
            "y": 1,
            "z": 18,
            "elements": [
                "nuclearcraft:electromagnet_supercooler_active@0"
            ]
        },
        {
